Workbook
Name DynDate: OFFSET(NAV!$B$3,0,0,COUNTA(NAV!$B:$B),1)
Name DynITD: OFFSET(NAV!$M$3,0,0,COUNTA(NAV!$M:$M)-1,1)
Name DynMTD: OFFSET(NAV!$N$3,0,0,COUNTA(NAV!$N:$N)-1,1)
Name DynNAV: OFFSET(NAV!$L$3,0,0,COUNTA(NAV!$L:$L)-1,1)

Sheet Blotter
B2: Data | C2: Close | E2: Equity | F2: Futures
B3: AUM | C3: =OFFSET(NAV!B1,MATCH(TODAY(),NAV!B:B,1),8) -> 0 | E3: Commodities | F3: Stocks
B4: P&L $ | C4: =SUM(N18:N1012) -> -516288.43 | E4: FX | F4: Call
B5: Performance ITD % | C5: =OFFSET(NAV!B1,MATCH(TODAY(),NAV!B:B,1),11) -> 0 | E5: Fixed income | F5: Put
B6: Performance MTD % | C6: =OFFSET(NAV!B1,MATCH(TODAY(),NAV!B:B,1),12) -> 0
B7: Risk-free P&L $ | C7: =Cash_Mgmt!H13 -> -3376 | D7: =C7/C3 -> #DIV/0!
B8: Projected P&L $ | C8: =C4+C7 -> -519664.43 | D8: =C5+D7 -> #DIV/0!
B9: Notional Futures $ | C9: {=SUM((F19:F112="Futures")*(M19:M112))} -> 0 | D9: =C9/$C$3 -> #DIV/0!
B10: Notional Call $ | C10: {=SUM((F19:F1012="Call")*(M19:M1012))} -> 0 | D10: =C10/$C$3 -> #DIV/0!
B11: Notional Put $ | C11: {=SUM((F19:F212="Put")*(M19:M212))} -> 0 | D11: =C11/$C$3 -> #DIV/0!
B12: Open Risk $ | C12: {=SUM((PLB!G4:G999="O")*(PLB!E4:E999))} -> 0 | D12: =C12/$C$3 -> #DIV/0!
B13: Open P&L $ | C13: {=SUM((PLB!G4:G999="O")*(PLB!D4:D999))} -> 0 | D13: =C13/$C$3 -> #DIV/0!
B14: PLB Risk $ | C14: =C12+C13 -> 0 | D14: =C14/$C$3 -> #DIV/0!
B17: TICKER | C17: WEEK | D17: UNDERLYING | E17: ASSET CLASS | F17: INSTRUMENT | G17: MAX QUANTITY | H17: INITIAL QUANTITY | I17: QUANTITY | J17: MULTIPLIER | K17: ENTRY PRICE | L17: EXIT PRICE | M17: NOTIONAL $ | N17: P&L $ | O17: ATR | P17: INITIAL RISK | Q17: ROLL | R17: INITIAL RISK $ | S17: VOL SL | T17: VOL/EXIT-1 | U17: TECH SL | V17: TECH/EXIT -1 | X17: <0 | Y17: >0 | Z17: Market Data
B18: CASH MGMT | E18: Fixed income | N18: =Cash_Mgmt!G13 -> 12955.38
B19: SPX 230616P03850000 | C19: 1 | D19: SPX | E19: Equity | F19: Put | G19: =IF(F19="Futures",VLOOKUP(D19,Multiplier!B:I,8,0),0) -> 0 | H19: 6 | I19: {=SUM((Trades!V$2:V$9999)*(Trades!U$2:U$9999=Blotter!B19)*(Trades!$T$2:T$9999=Blotter!C19))} -> 0 | J19: =VLOOKUP(D19,Multiplier!B:D,2,0) -> 100 | K19: =L19-N19/(H19*J19) -> 41.027231 | L19: =IF(I19=0,IF(H19>0,X19,Y19),Z19) -> 27 | M19: =I19*J19*L19 -> 0 | N19: {=-SUM((Trades!T$2:T$9999=Blotter!C19)*(Trades!U$2:U$9999=Blotter!B19)*(Trades!V$2:V$9999)*(Trades!W$2:W$9999))*J19+SUM((Trades!T$2:T$9999=Blotter!C19)*(Trades!U$2:U$9999=Blotter!B19)*(Trades!X$2:X$9999))+(L19*I19)*J19} -> -8416.3386 | O19: =VLOOKUP(D19,Multiplier!B:H,3,0) -> 42 | P19: 41 | R19: =(1-Q19)*P19*J19*H19 -> 24600 | S19: =IF(OR(F19="Futures",F19="Stocks"),IF(I19=0,0,IF(I19>0,L19-O19,L19+O19)),0) -> 0 | T19: =IF(S19>0,IF(ISNUMBER(S19/L19-1),S19/L19-1,0),0) -> 0 | U19: =IF(OR(F19="Futures",F19="Stocks"),IF(I19=0,0,IF(I19>0,K19-P19,K19+P19)),0) -> 0 | V19: =IF(U19>0,IF(ISNUMBER(U19/L19-1),U19/L19-1,0),0) -> 0 | X19: {=IF(ISNUMBER(SUM((Trades!T$2:T$9999=Blotter!C19)*(Trades!U$2:U$9999=Blotter!B19)*(Trades!W$2:W$9999)*(Trades!V$2:V$9999)*(Trades!V$2:V$9999<0))/SUM((Trades!T$2:T$9999=Blotter!C19)*(Trades!U$2:U$9999=Blotter!B19)*(Trades!V$2:V$9999)*(Trades!V$2:V$9999<0))),SUM((Trades!T$2:T$9999=Blotter!C19)*(Trades!U$2:U$9999=Blotter!B19)*(Trades!W$2:W$9999)*(Trades!V$2:V$9999)*(Trades!V$2:V$9999<0))/SUM((Trades!T$2:T$9999=Blotter!C19)*(Trades!U$2:U$9999=Blotter!B19)*(Trades!V$2:V$9999)*(Trades!V$2:V$9999<0)),0)} -> 27 | Y19: {=IF(ISNUMBER(SUM((Trades!T$2:T$9999=Blotter!C19)*(Trades!U$2:U$9999=Blotter!B19)*(Trades!W$2:W$9999)*(Trades!V$2:V$9999)*(Trades!V$2:V$9999>0))/SUM((Trades!T$2:T$9999=Blotter!C19)*(Trades!U$2:U$9999=Blotter!B19)*(Trades!V$2:V$9999)*(Trades!V$2:V$9999>0))),SUM((Trades!T$2:T$9999=Blotter!C19)*(Trades!U$2:U$9999=Blotter!B19)*(Trades!W$2:W$9999)*(Trades!V$2:V$9999)*(Trades!V$2:V$9999>0))/SUM((Trades!T$2:T$9999=Blotter!C19)*(Trades!U$2:U$9999=Blotter!B19)*(Trades!V$2:V$9999)*(Trades!V$2:V$9999>0)),0)} -> 41 | Z19: =IF(C$2="Last",IF(ISNUMBER(VLOOKUP(B19,Data_IB!B:O,14,0)),VLOOKUP(B19,Data_IB!B:O,14,0),0),IF(ISNUMBER(VLOOKUP(B19,Data_IB!B:O,13,0)),VLOOKUP(B19,Data_IB!B:O,13,0),0)) -> 0
B20: SPX 230616P03700000 | C20: 1 | D20: SPX | E20: Equity | F20: Put | G20: =IF(F20="Futures",VLOOKUP(D20,Multiplier!B:I,8,0),0) -> 0 | H20: -6 | I20: {=SUM((Trades!V$2:V$9999)*(Trades!U$2:U$9999=Blotter!B20)*(Trades!$T$2:T$9999=Blotter!C20))} -> 0 | J20: =VLOOKUP(D20,Multiplier!B:D,2,0) -> 100 | K20: =L20-N20/(H20*J20) -> 24.486384 | L20: =IF(I20=0,IF(H20>0,X20,Y20),Z20) -> 0 | M20: =I20*J20*L20 -> 0 | N20: {=-SUM((Trades!T$2:T$9999=Blotter!C20)*(Trades!U$2:U$9999=Blotter!B20)*(Trades!V$2:V$9999)*(Trades!W$2:W$9999))*J20+SUM((Trades!T$2:T$9999=Blotter!C20)*(Trades!U$2:U$9999=Blotter!B20)*(Trades!X$2:X$9999))+(L20*I20)*J20} -> 14691.831 | O20: =VLOOKUP(D20,Multiplier!B:H,3,0) -> 42 | P20: 24.5 | R20: =(1-Q20)*P20*J20*H20 -> -14700 | S20: =IF(OR(F20="Futures",F20="Stocks"),IF(I20=0,0,IF(I20>0,L20-O20,L20+O20)),0) -> 0 | T20: =IF(S20>0,IF(ISNUMBER(S20/L20-1),S20/L20-1,0),0) -> 0 | U20: =IF(OR(F20="Futures",F20="Stocks"),IF(I20=0,0,IF(I20>0,K20-P20,K20+P20)),0) -> 0 | V20: =IF(U20>0,IF(ISNUMBER(U20/L20-1),U20/L20-1,0),0) -> 0 | X20: {=IF(ISNUMBER(SUM((Trades!T$2:T$9999=Blotter!C20)*(Trades!U$2:U$9999=Blotter!B20)*(Trades!W$2:W$9999)*(Trades!V$2:V$9999)*(Trades!V$2:V$9999<0))/SUM((Trades!T$2:T$9999=Blotter!C20)*(Trades!U$2:U$9999=Blotter!B20)*(Trades!V$2:V$9999)*(Trades!V$2:V$9999<0))),SUM((Trades!T$2:T$9999=Blotter!C20)*(Trades!U$2:U$9999=Blotter!B20)*(Trades!W$2:W$9999)*(Trades!V$2:V$9999)*(Trades!V$2:V$9999<0))/SUM((Trades!T$2:T$9999=Blotter!C20)*(Trades!U$2:U$9999=Blotter!B20)*(Trades!V$2:V$9999)*(Trades!V$2:V$9999<0)),0)} -> 24.5 | Y20: {=IF(ISNUMBER(SUM((Trades!T$2:T$9999=Blotter!C20)*(Trades!U$2:U$9999=Blotter!B20)*(Trades!W$2:W$9999)*(Trades!V$2:V$9999)*(Trades!V$2:V$9999>0))/SUM((Trades!T$2:T$9999=Blotter!C20)*(Trades!U$2:U$9999=Blotter!B20)*(Trades!V$2:V$9999)*(Trades!V$2:V$9999>0))),SUM((Trades!T$2:T$9999=Blotter!C20)*(Trades!U$2:U$9999=Blotter!B20)*(Trades!W$2:W$9999)*(Trades!V$2:V$9999)*(Trades!V$2:V$9999>0))/SUM((Trades!T$2:T$9999=Blotter!C20)*(Trades!U$2:U$9999=Blotter!B20)*(Trades!V$2:V$9999)*(Trades!V$2:V$9999>0)),0)} -> 0 | Z20: =IF(C$2="Last",IF(ISNUMBER(VLOOKUP(B20,Data_IB!B:O,14,0)),VLOOKUP(B20,Data_IB!B:O,14,0),0),IF(ISNUMBER(VLOOKUP(B20,Data_IB!B:O,13,0)),VLOOKUP(B20,Data_IB!B:O,13,0),0)) -> 0
B21: NGK3 | C21: 2 | D21: NG | E21: Commodities | F21: Futures | G21: =IF(F21="Futures",VLOOKUP(D21,Multiplier!B:I,8,0),0) -> 8 | H21: 5 | I21: {=SUM((Trades!V$2:V$9999)*(Trades!U$2:U$9999=Blotter!B21)*(Trades!$T$2:T$9999=Blotter!C21))} -> 0 | J21: =VLOOKUP(D21,Multiplier!B:D,2,0) -> 10000 | K21: =L21-N21/(H21*J21) -> 2.208474 | L21: =IF(I21=0,IF(H21>0,X21,Y21),Z21) -> 2.25 | M21: =I21*J21*L21 -> 0 | N21: {=-SUM((Trades!T$2:T$9999=Blotter!C21)*(Trades!U$2:U$9999=Blotter!B21)*(Trades!V$2:V$9999)*(Trades!W$2:W$9999))*J21+SUM((Trades!T$2:T$9999=Blotter!C21)*(Trades!U$2:U$9999=Blotter!B21)*(Trades!X$2:X$9999))+(L21*I21)*J21} -> 2076.3 | O21: =VLOOKUP(D21,Multiplier!B:H,3,0) -> 0.132 | P21: 0.18 | R21: =(1-Q21)*P21*J21*H21 -> 9000 | S21: =IF(OR(F21="Futures",F21="Stocks"),IF(I21=0,0,IF(I21>0,L21-O21,L21+O21)),0) -> 0 | T21: =IF(S21>0,IF(ISNUMBER(S21/L21-1),S21/L21-1,0),0) -> 0 | U21: =IF(OR(F21="Futures",F21="Stocks"),IF(I21=0,0,IF(I21>0,K21-P21,K21+P21)),0) -> 0 | V21: =IF(U21>0,IF(ISNUMBER(U21/L21-1),U21/L21-1,0),0) -> 0 | X21: {=IF(ISNUMBER(SUM((Trades!T$2:T$9999=Blotter!C21)*(Trades!U$2:U$9999=Blotter!B21)*(Trades!W$2:W$9999)*(Trades!V$2:V$9999)*(Trades!V$2:V$9999<0))/SUM((Trades!T$2:T$9999=Blotter!C21)*(Trades!U$2:U$9999=Blotter!B21)*(Trades!V$2:V$9999)*(Trades!V$2:V$9999<0))),SUM((Trades!T$2:T$9999=Blotter!C21)*(Trades!U$2:U$9999=Blotter!B21)*(Trades!W$2:W$9999)*(Trades!V$2:V$9999)*(Trades!V$2:V$9999<0))/SUM((Trades!T$2:T$9999=Blotter!C21)*(Trades!U$2:U$9999=Blotter!B21)*(Trades!V$2:V$9999)*(Trades!V$2:V$9999<0)),0)} -> 2.25 | Y21: {=IF(ISNUMBER(SUM((Trades!T$2:T$9999=Blotter!C21)*(Trades!U$2:U$9999=Blotter!B21)*(Trades!W$2:W$9999)*(Trades!V$2:V$9999)*(Trades!V$2:V$9999>0))/SUM((Trades!T$2:T$9999=Blotter!C21)*(Trades!U$2:U$9999=Blotter!B21)*(Trades!V$2:V$9999)*(Trades!V$2:V$9999>0))),SUM((Trades!T$2:T$9999=Blotter!C21)*(Trades!U$2:U$9999=Blotter!B21)*(Trades!W$2:W$9999)*(Trades!V$2:V$9999)*(Trades!V$2:V$9999>0))/SUM((Trades!T$2:T$9999=Blotter!C21)*(Trades!U$2:U$9999=Blotter!B21)*(Trades!V$2:V$9999)*(Trades!V$2:V$9999>0)),0)} -> 2.208 | Z21: =IF(C$2="Last",IF(ISNUMBER(VLOOKUP(B21,Data_IB!B:O,14,0)),VLOOKUP(B21,Data_IB!B:O,14,0),0),IF(ISNUMBER(VLOOKUP(B21,Data_IB!B:O,13,0)),VLOOKUP(B21,Data_IB!B:O,13,0),0)) -> 0
B22: NGM3 | C22: 2 | D22: NG | E22: Commodities | F22: Futures | G22: =IF(F22="Futures",VLOOKUP(D22,Multiplier!B:I,8,0),0) -> 8 | H22: 5 | I22: {=SUM((Trades!V$2:V$9999)*(Trades!U$2:U$9999=Blotter!B22)*(Trades!$T$2:T$9999=Blotter!C22))} -> 0 | J22: =VLOOKUP(D22,Multiplier!B:D,2,0) -> 10000 | K22: =L22-N22/(H22*J22) -> 2.327448 | L22: =IF(I22=0,IF(H22>0,X22,Y22),Z22) -> 2.3075 | M22: =I22*J22*L22 -> 0 | N22: {=-SUM((Trades!T$2:T$9999=Blotter!C22)*(Trades!U$2:U$9999=Blotter!B22)*(Trades!V$2:V$9999)*(Trades!W$2:W$9999))*J22+SUM((Trades!T$2:T$9999=Blotter!C22)*(Trades!U$2:U$9999=Blotter!B22)*(Trades!X$2:X$9999))+(L22*I22)*J22} -> -997.4 | O22: =VLOOKUP(D22,Multiplier!B:H,3,0) -> 0.132 | P22: 0.18 | Q22: 1 | R22: =(1-Q22)*P22*J22*H22 -> 0 | S22: =IF(OR(F22="Futures",F22="Stocks"),IF(I22=0,0,IF(I22>0,L22-O22,L22+O22)),0) -> 0 | T22: =IF(S22>0,IF(ISNUMBER(S22/L22-1),S22/L22-1,0),0) -> 0 | U22: =IF(OR(F22="Futures",F22="Stocks"),IF(I22=0,0,IF(I22>0,K22-P22,K22+P22)),0) -> 0 | V22: =IF(U22>0,IF(ISNUMBER(U22/L22-1),U22/L22-1,0),0) -> 0 | X22: {=IF(ISNUMBER(SUM((Trades!T$2:T$9999=Blotter!C22)*(Trades!U$2:U$9999=Blotter!B22)*(Trades!W$2:W$9999)*(Trades!V$2:V$9999)*(Trades!V$2:V$9999<0))/SUM((Trades!T$2:T$9999=Blotter!C22)*(Trades!U$2:U$9999=Blotter!B22)*(Trades!V$2:V$9999)*(Trades!V$2:V$9999<0))),SUM((Trades!T$2:T$9999=Blotter!C22)*(Trades!U$2:U$9999=Blotter!B22)*(Trades!W$2:W$9999)*(Trades!V$2:V$9999)*(Trades!V$2:V$9999<0))/SUM((Trades!T$2:T$9999=Blotter!C22)*(Trades!U$2:U$9999=Blotter!B22)*(Trades!V$2:V$9999)*(Trades!V$2:V$9999<0)),0)} -> 2.3075 | Y22: {=IF(ISNUMBER(SUM((Trades!T$2:T$9999=Blotter!C22)*(Trades!U$2:U$9999=Blotter!B22)*(Trades!W$2:W$9999)*(Trades!V$2:V$9999)*(Trades!V$2:V$9999>0))/SUM((Trades!T$2:T$9999=Blotter!C22)*(Trades!U$2:U$9999=Blotter!B22)*(Trades!V$2:V$9999)*(Trades!V$2:V$9999>0))),SUM((Trades!T$2:T$9999=Blotter!C22)*(Trades!U$2:U$9999=Blotter!B22)*(Trades!W$2:W$9999)*(Trades!V$2:V$9999)*(Trades!V$2:V$9999>0))/SUM((Trades!T$2:T$9999=Blotter!C22)*(Trades!U$2:U$9999=Blotter!B22)*(Trades!V$2:V$9999)*(Trades!V$2:V$9999>0)),0)} -> 2.317 | Z22: =IF(C$2="Last",IF(ISNUMBER(VLOOKUP(B22,Data_IB!B:O,14,0)),VLOOKUP(B22,Data_IB!B:O,14,0),0),IF(ISNUMBER(VLOOKUP(B22,Data_IB!B:O,13,0)),VLOOKUP(B22,Data_IB!B:O,13,0),0)) -> 0
B23: NGN3 | C23: 2 | D23: NG | E23: Commodities | F23: Futures | G23: =IF(F23="Futures",VLOOKUP(D23,Multiplier!B:I,8,0),0) -> 8 | H23: 5 | I23: {=SUM((Trades!V$2:V$9999)*(Trades!U$2:U$9999=Blotter!B23)*(Trades!$T$2:T$9999=Blotter!C23))} -> 0 | J23: =VLOOKUP(D23,Multiplier!B:D,2,0) -> 10000 | K23: =L23-N23/(H23*J23) -> 2.3523549 | L23: =IF(I23=0,IF(H23>0,X23,Y23),Z23) -> 2.4208889 | M23: =I23*J23*L23 -> 0 | N23: {=-SUM((Trades!T$2:T$9999=Blotter!C23)*(Trades!U$2:U$9999=Blotter!B23)*(Trades!V$2:V$9999)*(Trades!W$2:W$9999))*J23+SUM((Trades!T$2:T$9999=Blotter!C23)*(Trades!U$2:U$9999=Blotter!B23)*(Trades!X$2:X$9999))+(L23*I23)*J23} -> 3426.7 | O23: =VLOOKUP(D23,Multiplier!B:H,3,0) -> 0.132 | P23: 0.18 | Q23: 1 | R23: =(1-Q23)*P23*J23*H23 -> 0 | S23: =IF(OR(F23="Futures",F23="Stocks"),IF(I23=0,0,IF(I23>0,L23-O23,L23+O23)),0) -> 0 | T23: =IF(S23>0,IF(ISNUMBER(S23/L23-1),S23/L23-1,0),0) -> 0 | U23: =IF(OR(F23="Futures",F23="Stocks"),IF(I23=0,0,IF(I23>0,K23-P23,K23+P23)),0) -> 0 | V23: =IF(U23>0,IF(ISNUMBER(U23/L23-1),U23/L23-1,0),0) -> 0 | X23: {=IF(ISNUMBER(SUM((Trades!T$2:T$9999=Blotter!C23)*(Trades!U$2:U$9999=Blotter!B23)*(Trades!W$2:W$9999)*(Trades!V$2:V$9999)*(Trades!V$2:V$9999<0))/SUM((Trades!T$2:T$9999=Blotter!C23)*(Trades!U$2:U$9999=Blotter!B23)*(Trades!V$2:V$9999)*(Trades!V$2:V$9999<0))),SUM((Trades!T$2:T$9999=Blotter!C23)*(Trades!U$2:U$9999=Blotter!B23)*(Trades!W$2:W$9999)*(Trades!V$2:V$9999)*(Trades!V$2:V$9999<0))/SUM((Trades!T$2:T$9999=Blotter!C23)*(Trades!U$2:U$9999=Blotter!B23)*(Trades!V$2:V$9999)*(Trades!V$2:V$9999<0)),0)} -> 2.4208889 | Y23: {=IF(ISNUMBER(SUM((Trades!T$2:T$9999=Blotter!C23)*(Trades!U$2:U$9999=Blotter!B23)*(Trades!W$2:W$9999)*(Trades!V$2:V$9999)*(Trades!V$2:V$9999>0))/SUM((Trades!T$2:T$9999=Blotter!C23)*(Trades!U$2:U$9999=Blotter!B23)*(Trades!V$2:V$9999)*(Trades!V$2:V$9999>0))),SUM((Trades!T$2:T$9999=Blotter!C23)*(Trades!U$2:U$9999=Blotter!B23)*(Trades!W$2:W$9999)*(Trades!V$2:V$9999)*(Trades!V$2:V$9999>0))/SUM((Trades!T$2:T$9999=Blotter!C23)*(Trades!U$2:U$9999=Blotter!B23)*(Trades!V$2:V$9999)*(Trades!V$2:V$9999>0)),0)} -> 2.4128 | Z23: =IF(C$2="Last",IF(ISNUMBER(VLOOKUP(B23,Data_IB!B:O,14,0)),VLOOKUP(B23,Data_IB!B:O,14,0),0),IF(ISNUMBER(VLOOKUP(B23,Data_IB!B:O,13,0)),VLOOKUP(B23,Data_IB!B:O,13,0),0)) -> 0
B24: RBM3 | C24: 3 | D24: RB | E24: Commodities | F24: Futures | G24: =IF(F24="Futures",VLOOKUP(D24,Multiplier!B:I,8,0),0) -> 3 | H24: 2 | I24: {=SUM((Trades!V$2:V$9999)*(Trades!U$2:U$9999=Blotter!B24)*(Trades!$T$2:T$9999=Blotter!C24))} -> 0 | J24: =VLOOKUP(D24,Multiplier!B:D,2,0) -> 42000 | K24: =L24-N24/(H24*J24) -> 2.5630507 | L24: =IF(I24=0,IF(H24>0,X24,Y24),Z24) -> 2.542175 | M24: =I24*J24*L24 -> 0 | N24: {=-SUM((Trades!T$2:T$9999=Blotter!C24)*(Trades!U$2:U$9999=Blotter!B24)*(Trades!V$2:V$9999)*(Trades!W$2:W$9999))*J24+SUM((Trades!T$2:T$9999=Blotter!C24)*(Trades!U$2:U$9999=Blotter!B24)*(Trades!X$2:X$9999))+(L24*I24)*J24} -> -1753.56 | O24: =VLOOKUP(D24,Multiplier!B:H,3,0) -> 0.0725 | P24: 0.1 | R24: =(1-Q24)*P24*J24*H24 -> 8400 | S24: =IF(OR(F24="Futures",F24="Stocks"),IF(I24=0,0,IF(I24>0,L24-O24,L24+O24)),0) -> 0 | T24: =IF(S24>0,IF(ISNUMBER(S24/L24-1),S24/L24-1,0),0) -> 0 | U24: =IF(OR(F24="Futures",F24="Stocks"),IF(I24=0,0,IF(I24>0,K24-P24,K24+P24)),0) -> 0 | V24: =IF(U24>0,IF(ISNUMBER(U24/L24-1),U24/L24-1,0),0) -> 0 | X24: {=IF(ISNUMBER(SUM((Trades!T$2:T$9999=Blotter!C24)*(Trades!U$2:U$9999=Blotter!B24)*(Trades!W$2:W$9999)*(Trades!V$2:V$9999)*(Trades!V$2:V$9999<0))/SUM((Trades!T$2:T$9999=Blotter!C24)*(Trades!U$2:U$9999=Blotter!B24)*(Trades!V$2:V$9999)*(Trades!V$2:V$9999<0))),SUM((Trades!T$2:T$9999=Blotter!C24)*(Trades!U$2:U$9999=Blotter!B24)*(Trades!W$2:W$9999)*(Trades!V$2:V$9999)*(Trades!V$2:V$9999<0))/SUM((Trades!T$2:T$9999=Blotter!C24)*(Trades!U$2:U$9999=Blotter!B24)*(Trades!V$2:V$9999)*(Trades!V$2:V$9999<0)),0)} -> 2.542175 | Y24: {=IF(ISNUMBER(SUM((Trades!T$2:T$9999=Blotter!C24)*(Trades!U$2:U$9999=Blotter!B24)*(Trades!W$2:W$9999)*(Trades!V$2:V$9999)*(Trades!V$2:V$9999>0))/SUM((Trades!T$2:T$9999=Blotter!C24)*(Trades!U$2:U$9999=Blotter!B24)*(Trades!V$2:V$9999)*(Trades!V$2:V$9999>0))),SUM((Trades!T$2:T$9999=Blotter!C24)*(Trades!U$2:U$9999=Blotter!B24)*(Trades!W$2:W$9999)*(Trades!V$2:V$9999)*(Trades!V$2:V$9999>0))/SUM((Trades!T$2:T$9999=Blotter!C24)*(Trades!U$2:U$9999=Blotter!B24)*(Trades!V$2:V$9999)*(Trades!V$2:V$9999>0)),0)} -> 2.5525 | Z24: =IF(C$2="Last",IF(ISNUMBER(VLOOKUP(B24,Data_IB!B:O,14,0)),VLOOKUP(B24,Data_IB!B:O,14,0),0),IF(ISNUMBER(VLOOKUP(B24,Data_IB!B:O,13,0)),VLOOKUP(B24,Data_IB!B:O,13,0),0)) -> 0
B25: QNEM3 C13800 | C25: 5 | D25: NQ | E25: Equity | F25: Call | G25: =IF(F25="Futures",VLOOKUP(D25,Multiplier!B:I,8,0),0) -> 0 | H25: 1 | I25: {=SUM((Trades!V$2:V$9999)*(Trades!U$2:U$9999=Blotter!B25)*(Trades!$T$2:T$9999=Blotter!C25))} -> 0 | J25: =VLOOKUP(D25,Multiplier!B:D,2,0) -> 20 | K25: =L25-N25/(H25*J25) -> 205.142 | L25: =IF(I25=0,IF(H25>0,X25,Y25),Z25) -> 275 | M25: =I25*J25*L25 -> 0 | N25: {=-SUM((Trades!T$2:T$9999=Blotter!C25)*(Trades!U$2:U$9999=Blotter!B25)*(Trades!V$2:V$9999)*(Trades!W$2:W$9999))*J25+SUM((Trades!T$2:T$9999=Blotter!C25)*(Trades!U$2:U$9999=Blotter!B25)*(Trades!X$2:X$9999))+(L25*I25)*J25} -> 1397.16 | O25: =VLOOKUP(D25,Multiplier!B:H,3,0) -> 248 | P25: 205 | R25: =(1-Q25)*P25*J25*H25 -> 4100 | S25: =IF(OR(F25="Futures",F25="Stocks"),IF(I25=0,0,IF(I25>0,L25-O25,L25+O25)),0) -> 0 | T25: =IF(S25>0,IF(ISNUMBER(S25/L25-1),S25/L25-1,0),0) -> 0 | U25: =IF(OR(F25="Futures",F25="Stocks"),IF(I25=0,0,IF(I25>0,K25-P25,K25+P25)),0) -> 0 | V25: =IF(U25>0,IF(ISNUMBER(U25/L25-1),U25/L25-1,0),0) -> 0 | X25: {=IF(ISNUMBER(SUM((Trades!T$2:T$9999=Blotter!C25)*(Trades!U$2:U$9999=Blotter!B25)*(Trades!W$2:W$9999)*(Trades!V$2:V$9999)*(Trades!V$2:V$9999<0))/SUM((Trades!T$2:T$9999=Blotter!C25)*(Trades!U$2:U$9999=Blotter!B25)*(Trades!V$2:V$9999)*(Trades!V$2:V$9999<0))),SUM((Trades!T$2:T$9999=Blotter!C25)*(Trades!U$2:U$9999=Blotter!B25)*(Trades!W$2:W$9999)*(Trades!V$2:V$9999)*(Trades!V$2:V$9999<0))/SUM((Trades!T$2:T$9999=Blotter!C25)*(Trades!U$2:U$9999=Blotter!B25)*(Trades!V$2:V$9999)*(Trades!V$2:V$9999<0)),0)} -> 275 | Y25: {=IF(ISNUMBER(SUM((Trades!T$2:T$9999=Blotter!C25)*(Trades!U$2:U$9999=Blotter!B25)*(Trades!W$2:W$9999)*(Trades!V$2:V$9999)*(Trades!V$2:V$9999>0))/SUM((Trades!T$2:T$9999=Blotter!C25)*(Trades!U$2:U$9999=Blotter!B25)*(Trades!V$2:V$9999)*(Trades!V$2:V$9999>0))),SUM((Trades!T$2:T$9999=Blotter!C25)*(Trades!U$2:U$9999=Blotter!B25)*(Trades!W$2:W$9999)*(Trades!V$2:V$9999)*(Trades!V$2:V$9999>0))/SUM((Trades!T$2:T$9999=Blotter!C25)*(Trades!U$2:U$9999=Blotter!B25)*(Trades!V$2:V$9999)*(Trades!V$2:V$9999>0)),0)} -> 205 | Z25: =IF(C$2="Last",IF(ISNUMBER(VLOOKUP(B25,Data_IB!B:O,14,0)),VLOOKUP(B25,Data_IB!B:O,14,0),0),IF(ISNUMBER(VLOOKUP(B25,Data_IB!B:O,13,0)),VLOOKUP(B25,Data_IB!B:O,13,0),0)) -> 0
B26: NQM3 | C26: 5 | D26: NQ | E26: Equity | F26: Futures | G26: =IF(F26="Futures",VLOOKUP(D26,Multiplier!B:I,8,0),0) -> 2 | H26: 1 | I26: {=SUM((Trades!V$2:V$9999)*(Trades!U$2:U$9999=Blotter!B26)*(Trades!$T$2:T$9999=Blotter!C26))} -> 0 | J26: =VLOOKUP(D26,Multiplier!B:D,2,0) -> 20 | K26: =L26-N26/(H26*J26) -> 13290.22 | L26: =IF(I26=0,IF(H26>0,X26,Y26),Z26) -> 13800 | M26: =I26*J26*L26 -> 0 | N26: {=-SUM((Trades!T$2:T$9999=Blotter!C26)*(Trades!U$2:U$9999=Blotter!B26)*(Trades!V$2:V$9999)*(Trades!W$2:W$9999))*J26+SUM((Trades!T$2:T$9999=Blotter!C26)*(Trades!U$2:U$9999=Blotter!B26)*(Trades!X$2:X$9999))+(L26*I26)*J26} -> 10195.6 | O26: =VLOOKUP(D26,Multiplier!B:H,3,0) -> 248 | P26: 250 | R26: =(1-Q26)*P26*J26*H26 -> 5000 | S26: =IF(OR(F26="Futures",F26="Stocks"),IF(I26=0,0,IF(I26>0,L26-O26,L26+O26)),0) -> 0 | T26: =IF(S26>0,IF(ISNUMBER(S26/L26-1),S26/L26-1,0),0) -> 0 | U26: =IF(OR(F26="Futures",F26="Stocks"),IF(I26=0,0,IF(I26>0,K26-P26,K26+P26)),0) -> 0 | V26: =IF(U26>0,IF(ISNUMBER(U26/L26-1),U26/L26-1,0),0) -> 0 | X26: {=IF(ISNUMBER(SUM((Trades!T$2:T$9999=Blotter!C26)*(Trades!U$2:U$9999=Blotter!B26)*(Trades!W$2:W$9999)*(Trades!V$2:V$9999)*(Trades!V$2:V$9999<0))/SUM((Trades!T$2:T$9999=Blotter!C26)*(Trades!U$2:U$9999=Blotter!B26)*(Trades!V$2:V$9999)*(Trades!V$2:V$9999<0))),SUM((Trades!T$2:T$9999=Blotter!C26)*(Trades!U$2:U$9999=Blotter!B26)*(Trades!W$2:W$9999)*(Trades!V$2:V$9999)*(Trades!V$2:V$9999<0))/SUM((Trades!T$2:T$9999=Blotter!C26)*(Trades!U$2:U$9999=Blotter!B26)*(Trades!V$2:V$9999)*(Trades!V$2:V$9999<0)),0)} -> 13800 | Y26: {=IF(ISNUMBER(SUM((Trades!T$2:T$9999=Blotter!C26)*(Trades!U$2:U$9999=Blotter!B26)*(Trades!W$2:W$9999)*(Trades!V$2:V$9999)*(Trades!V$2:V$9999>0))/SUM((Trades!T$2:T$9999=Blotter!C26)*(Trades!U$2:U$9999=Blotter!B26)*(Trades!V$2:V$9999)*(Trades!V$2:V$9999>0))),SUM((Trades!T$2:T$9999=Blotter!C26)*(Trades!U$2:U$9999=Blotter!B26)*(Trades!W$2:W$9999)*(Trades!V$2:V$9999)*(Trades!V$2:V$9999>0))/SUM((Trades!T$2:T$9999=Blotter!C26)*(Trades!U$2:U$9999=Blotter!B26)*(Trades!V$2:V$9999)*(Trades!V$2:V$9999>0)),0)} -> 13290 | Z26: =IF(C$2="Last",IF(ISNUMBER(VLOOKUP(B26,Data_IB!B:O,14,0)),VLOOKUP(B26,Data_IB!B:O,14,0),0),IF(ISNUMBER(VLOOKUP(B26,Data_IB!B:O,13,0)),VLOOKUP(B26,Data_IB!B:O,13,0),0)) -> 0
B27: SIN3 | C27: 6 | D27: SI | E27: Commodities | F27: Futures | G27: =IF(F27="Futures",VLOOKUP(D27,Multiplier!B:I,8,0),0) -> 2 | H27: 3 | I27: {=SUM((Trades!V$2:V$9999)*(Trades!U$2:U$9999=Blotter!B27)*(Trades!$T$2:T$9999=Blotter!C27))} -> 0 | J27: =VLOOKUP(D27,Multiplier!B:D,2,0) -> 5000 | K27: =L27-N27/(H27*J27) -> 24.662613 | L27: =IF(I27=0,IF(H27>0,X27,Y27),Z27) -> 23.151429 | M27: =I27*J27*L27 -> 0 | N27: {=-SUM((Trades!T$2:T$9999=Blotter!C27)*(Trades!U$2:U$9999=Blotter!B27)*(Trades!V$2:V$9999)*(Trades!W$2:W$9999))*J27+SUM((Trades!T$2:T$9999=Blotter!C27)*(Trades!U$2:U$9999=Blotter!B27)*(Trades!X$2:X$9999))+(L27*I27)*J27} -> -22667.76 | O27: =VLOOKUP(D27,Multiplier!B:H,3,0) -> 0.825 | P27: 0.64 | Q27: 1 | R27: =(1-Q27)*P27*J27*H27 -> 0 | S27: =IF(OR(F27="Futures",F27="Stocks"),IF(I27=0,0,IF(I27>0,L27-O27,L27+O27)),0) -> 0 | T27: =IF(S27>0,IF(ISNUMBER(S27/L27-1),S27/L27-1,0),0) -> 0 | U27: =IF(OR(F27="Futures",F27="Stocks"),IF(I27=0,0,IF(I27>0,K27-P27,K27+P27)),0) -> 0 | V27: =IF(U27>0,IF(ISNUMBER(U27/L27-1),U27/L27-1,0),0) -> 0 | X27: {=IF(ISNUMBER(SUM((Trades!T$2:T$9999=Blotter!C27)*(Trades!U$2:U$9999=Blotter!B27)*(Trades!W$2:W$9999)*(Trades!V$2:V$9999)*(Trades!V$2:V$9999<0))/SUM((Trades!T$2:T$9999=Blotter!C27)*(Trades!U$2:U$9999=Blotter!B27)*(Trades!V$2:V$9999)*(Trades!V$2:V$9999<0))),SUM((Trades!T$2:T$9999=Blotter!C27)*(Trades!U$2:U$9999=Blotter!B27)*(Trades!W$2:W$9999)*(Trades!V$2:V$9999)*(Trades!V$2:V$9999<0))/SUM((Trades!T$2:T$9999=Blotter!C27)*(Trades!U$2:U$9999=Blotter!B27)*(Trades!V$2:V$9999)*(Trades!V$2:V$9999<0)),0)} -> 23.151429 | Y27: {=IF(ISNUMBER(SUM((Trades!T$2:T$9999=Blotter!C27)*(Trades!U$2:U$9999=Blotter!B27)*(Trades!W$2:W$9999)*(Trades!V$2:V$9999)*(Trades!V$2:V$9999>0))/SUM((Trades!T$2:T$9999=Blotter!C27)*(Trades!U$2:U$9999=Blotter!B27)*(Trades!V$2:V$9999)*(Trades!V$2:V$9999>0))),SUM((Trades!T$2:T$9999=Blotter!C27)*(Trades!U$2:U$9999=Blotter!B27)*(Trades!W$2:W$9999)*(Trades!V$2:V$9999)*(Trades!V$2:V$9999>0))/SUM((Trades!T$2:T$9999=Blotter!C27)*(Trades!U$2:U$9999=Blotter!B27)*(Trades!V$2:V$9999)*(Trades!V$2:V$9999>0)),0)} -> 23.474286 | Z27: =IF(C$2="Last",IF(ISNUMBER(VLOOKUP(B27,Data_IB!B:O,14,0)),VLOOKUP(B27,Data_IB!B:O,14,0),0),IF(ISNUMBER(VLOOKUP(B27,Data_IB!B:O,13,0)),VLOOKUP(B27,Data_IB!B:O,13,0),0)) -> 0
B28: SIU3 | C28: 6 | D28: SI | E28: Commodities | F28: Futures | G28: =IF(F28="Futures",VLOOKUP(D28,Multiplier!B:I,8,0),0) -> 2 | H28: 3 | I28: {=SUM((Trades!V$2:V$9999)*(Trades!U$2:U$9999=Blotter!B28)*(Trades!$T$2:T$9999=Blotter!C28))} -> 0 | J28: =VLOOKUP(D28,Multiplier!B:D,2,0) -> 5000 | K28: =L28-N28/(H28*J28) -> 25.006949 | L28: =IF(I28=0,IF(H28>0,X28,Y28),Z28) -> 23.765128 | M28: =I28*J28*L28 -> 0 | N28: {=-SUM((Trades!T$2:T$9999=Blotter!C28)*(Trades!U$2:U$9999=Blotter!B28)*(Trades!V$2:V$9999)*(Trades!W$2:W$9999))*J28+SUM((Trades!T$2:T$9999=Blotter!C28)*(Trades!U$2:U$9999=Blotter!B28)*(Trades!X$2:X$9999))+(L28*I28)*J28} -> -18627.32 | O28: =VLOOKUP(D28,Multiplier!B:H,3,0) -> 0.825 | P28: 0.64 | Q28: 1 | R28: =(1-Q28)*P28*J28*H28 -> 0 | S28: =IF(OR(F28="Futures",F28="Stocks"),IF(I28=0,0,IF(I28>0,L28-O28,L28+O28)),0) -> 0 | T28: =IF(S28>0,IF(ISNUMBER(S28/L28-1),S28/L28-1,0),0) -> 0 | U28: =IF(OR(F28="Futures",F28="Stocks"),IF(I28=0,0,IF(I28>0,K28-P28,K28+P28)),0) -> 0 | V28: =IF(U28>0,IF(ISNUMBER(U28/L28-1),U28/L28-1,0),0) -> 0 | X28: {=IF(ISNUMBER(SUM((Trades!T$2:T$9999=Blotter!C28)*(Trades!U$2:U$9999=Blotter!B28)*(Trades!W$2:W$9999)*(Trades!V$2:V$9999)*(Trades!V$2:V$9999<0))/SUM((Trades!T$2:T$9999=Blotter!C28)*(Trades!U$2:U$9999=Blotter!B28)*(Trades!V$2:V$9999)*(Trades!V$2:V$9999<0))),SUM((Trades!T$2:T$9999=Blotter!C28)*(Trades!U$2:U$9999=Blotter!B28)*(Trades!W$2:W$9999)*(Trades!V$2:V$9999)*(Trades!V$2:V$9999<0))/SUM((Trades!T$2:T$9999=Blotter!C28)*(Trades!U$2:U$9999=Blotter!B28)*(Trades!V$2:V$9999)*(Trades!V$2:V$9999<0)),0)} -> 23.765128 | Y28: {=IF(ISNUMBER(SUM((Trades!T$2:T$9999=Blotter!C28)*(Trades!U$2:U$9999=Blotter!B28)*(Trades!W$2:W$9999)*(Trades!V$2:V$9999)*(Trades!V$2:V$9999>0))/SUM((Trades!T$2:T$9999=Blotter!C28)*(Trades!U$2:U$9999=Blotter!B28)*(Trades!V$2:V$9999)*(Trades!V$2:V$9999>0))),SUM((Trades!T$2:T$9999=Blotter!C28)*(Trades!U$2:U$9999=Blotter!B28)*(Trades!W$2:W$9999)*(Trades!V$2:V$9999)*(Trades!V$2:V$9999>0))/SUM((Trades!T$2:T$9999=Blotter!C28)*(Trades!U$2:U$9999=Blotter!B28)*(Trades!V$2:V$9999)*(Trades!V$2:V$9999>0)),0)} -> 23.770958 | Z28: =IF(C$2="Last",IF(ISNUMBER(VLOOKUP(B28,Data_IB!B:O,14,0)),VLOOKUP(B28,Data_IB!B:O,14,0),0),IF(ISNUMBER(VLOOKUP(B28,Data_IB!B:O,13,0)),VLOOKUP(B28,Data_IB!B:O,13,0),0)) -> 0
B29: SIZ3 | C29: 6 | D29: SI | E29: Commodities | F29: Futures | G29: =IF(F29="Futures",VLOOKUP(D29,Multiplier!B:I,8,0),0) -> 2 | H29: 3 | I29: {=SUM((Trades!V$2:V$9999)*(Trades!U$2:U$9999=Blotter!B29)*(Trades!$T$2:T$9999=Blotter!C29))} -> 0 | J29: =VLOOKUP(D29,Multiplier!B:D,2,0) -> 5000 | K29: =L29-N29/(H29*J29) -> 28.300641 | L29: =IF(I29=0,IF(H29>0,X29,Y29),Z29) -> 23.567577 | M29: =I29*J29*L29 -> 0 | N29: {=-SUM((Trades!T$2:T$9999=Blotter!C29)*(Trades!U$2:U$9999=Blotter!B29)*(Trades!V$2:V$9999)*(Trades!W$2:W$9999))*J29+SUM((Trades!T$2:T$9999=Blotter!C29)*(Trades!U$2:U$9999=Blotter!B29)*(Trades!X$2:X$9999))+(L29*I29)*J29} -> -70995.96 | O29: =VLOOKUP(D29,Multiplier!B:H,3,0) -> 0.825 | P29: 0.64 | Q29: 1 | R29: =(1-Q29)*P29*J29*H29 -> 0 | S29: =IF(OR(F29="Futures",F29="Stocks"),IF(I29=0,0,IF(I29>0,L29-O29,L29+O29)),0) -> 0 | T29: =IF(S29>0,IF(ISNUMBER(S29/L29-1),S29/L29-1,0),0) -> 0 | U29: =IF(OR(F29="Futures",F29="Stocks"),IF(I29=0,0,IF(I29>0,K29-P29,K29+P29)),0) -> 0 | V29: =IF(U29>0,IF(ISNUMBER(U29/L29-1),U29/L29-1,0),0) -> 0 | X29: {=IF(ISNUMBER(SUM((Trades!T$2:T$9999=Blotter!C29)*(Trades!U$2:U$9999=Blotter!B29)*(Trades!W$2:W$9999)*(Trades!V$2:V$9999)*(Trades!V$2:V$9999<0))/SUM((Trades!T$2:T$9999=Blotter!C29)*(Trades!U$2:U$9999=Blotter!B29)*(Trades!V$2:V$9999)*(Trades!V$2:V$9999<0))),SUM((Trades!T$2:T$9999=Blotter!C29)*(Trades!U$2:U$9999=Blotter!B29)*(Trades!W$2:W$9999)*(Trades!V$2:V$9999)*(Trades!V$2:V$9999<0))/SUM((Trades!T$2:T$9999=Blotter!C29)*(Trades!U$2:U$9999=Blotter!B29)*(Trades!V$2:V$9999)*(Trades!V$2:V$9999<0)),0)} -> 23.567577 | Y29: {=IF(ISNUMBER(SUM((Trades!T$2:T$9999=Blotter!C29)*(Trades!U$2:U$9999=Blotter!B29)*(Trades!W$2:W$9999)*(Trades!V$2:V$9999)*(Trades!V$2:V$9999>0))/SUM((Trades!T$2:T$9999=Blotter!C29)*(Trades!U$2:U$9999=Blotter!B29)*(Trades!V$2:V$9999)*(Trades!V$2:V$9999>0))),SUM((Trades!T$2:T$9999=Blotter!C29)*(Trades!U$2:U$9999=Blotter!B29)*(Trades!W$2:W$9999)*(Trades!V$2:V$9999)*(Trades!V$2:V$9999>0))/SUM((Trades!T$2:T$9999=Blotter!C29)*(Trades!U$2:U$9999=Blotter!B29)*(Trades!V$2:V$9999)*(Trades!V$2:V$9999>0)),0)} -> 23.589548 | Z29: =IF(C$2="Last",IF(ISNUMBER(VLOOKUP(B29,Data_IB!B:O,14,0)),VLOOKUP(B29,Data_IB!B:O,14,0),0),IF(ISNUMBER(VLOOKUP(B29,Data_IB!B:O,13,0)),VLOOKUP(B29,Data_IB!B:O,13,0),0)) -> 0
B30: SOZ3 P2000 | C30: 6 | D30: SI | E30: Commodities | F30: Put | G30: =IF(F30="Futures",VLOOKUP(D30,Multiplier!B:I,8,0),0) -> 0 | H30: -15 | I30: {=SUM((Trades!V$2:V$9999)*(Trades!U$2:U$9999=Blotter!B30)*(Trades!$T$2:T$9999=Blotter!C30))} -> 0 | J30: =VLOOKUP(D30,Multiplier!B:D,2,0) -> 5000 | K30: =L30-N30/(H30*J30) -> 0.359052 | L30: =IF(I30=0,IF(H30>0,X30,Y30),Z30) -> 0.13 | M30: =I30*J30*L30 -> 0 | N30: {=-SUM((Trades!T$2:T$9999=Blotter!C30)*(Trades!U$2:U$9999=Blotter!B30)*(Trades!V$2:V$9999)*(Trades!W$2:W$9999))*J30+SUM((Trades!T$2:T$9999=Blotter!C30)*(Trades!U$2:U$9999=Blotter!B30)*(Trades!X$2:X$9999))+(L30*I30)*J30} -> 17178.9 | O30: =VLOOKUP(D30,Multiplier!B:H,3,0) -> 0.825 | P30: 0.36 | Q30: 1 | R30: =(1-Q30)*P30*J30*H30 -> 0 | S30: =IF(OR(F30="Futures",F30="Stocks"),IF(I30=0,0,IF(I30>0,L30-O30,L30+O30)),0) -> 0 | T30: =IF(S30>0,IF(ISNUMBER(S30/L30-1),S30/L30-1,0),0) -> 0 | U30: =IF(OR(F30="Futures",F30="Stocks"),IF(I30=0,0,IF(I30>0,K30-P30,K30+P30)),0) -> 0 | V30: =IF(U30>0,IF(ISNUMBER(U30/L30-1),U30/L30-1,0),0) -> 0 | X30: {=IF(ISNUMBER(SUM((Trades!T$2:T$9999=Blotter!C30)*(Trades!U$2:U$9999=Blotter!B30)*(Trades!W$2:W$9999)*(Trades!V$2:V$9999)*(Trades!V$2:V$9999<0))/SUM((Trades!T$2:T$9999=Blotter!C30)*(Trades!U$2:U$9999=Blotter!B30)*(Trades!V$2:V$9999)*(Trades!V$2:V$9999<0))),SUM((Trades!T$2:T$9999=Blotter!C30)*(Trades!U$2:U$9999=Blotter!B30)*(Trades!W$2:W$9999)*(Trades!V$2:V$9999)*(Trades!V$2:V$9999<0))/SUM((Trades!T$2:T$9999=Blotter!C30)*(Trades!U$2:U$9999=Blotter!B30)*(Trades!V$2:V$9999)*(Trades!V$2:V$9999<0)),0)} -> 0.36 | Y30: {=IF(ISNUMBER(SUM((Trades!T$2:T$9999=Blotter!C30)*(Trades!U$2:U$9999=Blotter!B30)*(Trades!W$2:W$9999)*(Trades!V$2:V$9999)*(Trades!V$2:V$9999>0))/SUM((Trades!T$2:T$9999=Blotter!C30)*(Trades!U$2:U$9999=Blotter!B30)*(Trades!V$2:V$9999)*(Trades!V$2:V$9999>0))),SUM((Trades!T$2:T$9999=Blotter!C30)*(Trades!U$2:U$9999=Blotter!B30)*(Trades!W$2:W$9999)*(Trades!V$2:V$9999)*(Trades!V$2:V$9999>0))/SUM((Trades!T$2:T$9999=Blotter!C30)*(Trades!U$2:U$9999=Blotter!B30)*(Trades!V$2:V$9999)*(Trades!V$2:V$9999>0)),0)} -> 0.13 | Z30: =IF(C$2="Last",IF(ISNUMBER(VLOOKUP(B30,Data_IB!B:O,14,0)),VLOOKUP(B30,Data_IB!B:O,14,0),0),IF(ISNUMBER(VLOOKUP(B30,Data_IB!B:O,13,0)),VLOOKUP(B30,Data_IB!B:O,13,0),0)) -> 0
B31: SOZ3 C2220 | C31: 6 | D31: SI | E31: Commodities | F31: Call | G31: =IF(F31="Futures",VLOOKUP(D31,Multiplier!B:I,8,0),0) -> 0 | H31: 15 | I31: {=SUM((Trades!V$2:V$9999)*(Trades!U$2:U$9999=Blotter!B31)*(Trades!$T$2:T$9999=Blotter!C31))} -> 0 | J31: =VLOOKUP(D31,Multiplier!B:D,2,0) -> 5000 | K31: =L31-N31/(H31*J31) -> 0.34959733 | L31: =IF(I31=0,IF(H31>0,X31,Y31),Z31) -> 1.685 | M31: =I31*J31*L31 -> 0 | N31: {=-SUM((Trades!T$2:T$9999=Blotter!C31)*(Trades!U$2:U$9999=Blotter!B31)*(Trades!V$2:V$9999)*(Trades!W$2:W$9999))*J31+SUM((Trades!T$2:T$9999=Blotter!C31)*(Trades!U$2:U$9999=Blotter!B31)*(Trades!X$2:X$9999))+(L31*I31)*J31} -> 100155.2 | O31: =VLOOKUP(D31,Multiplier!B:H,3,0) -> 0.825 | P31: =0.52-0.23 -> 0.29 | Q31: 1 | R31: =(1-Q31)*P31*J31*H31 -> 0 | S31: =IF(OR(F31="Futures",F31="Stocks"),IF(I31=0,0,IF(I31>0,L31-O31,L31+O31)),0) -> 0 | T31: =IF(S31>0,IF(ISNUMBER(S31/L31-1),S31/L31-1,0),0) -> 0 | U31: =IF(OR(F31="Futures",F31="Stocks"),IF(I31=0,0,IF(I31>0,K31-P31,K31+P31)),0) -> 0 | V31: =IF(U31>0,IF(ISNUMBER(U31/L31-1),U31/L31-1,0),0) -> 0 | X31: {=IF(ISNUMBER(SUM((Trades!T$2:T$9999=Blotter!C31)*(Trades!U$2:U$9999=Blotter!B31)*(Trades!W$2:W$9999)*(Trades!V$2:V$9999)*(Trades!V$2:V$9999<0))/SUM((Trades!T$2:T$9999=Blotter!C31)*(Trades!U$2:U$9999=Blotter!B31)*(Trades!V$2:V$9999)*(Trades!V$2:V$9999<0))),SUM((Trades!T$2:T$9999=Blotter!C31)*(Trades!U$2:U$9999=Blotter!B31)*(Trades!W$2:W$9999)*(Trades!V$2:V$9999)*(Trades!V$2:V$9999<0))/SUM((Trades!T$2:T$9999=Blotter!C31)*(Trades!U$2:U$9999=Blotter!B31)*(Trades!V$2:V$9999)*(Trades!V$2:V$9999<0)),0)} -> 1.685 | Y31: {=IF(ISNUMBER(SUM((Trades!T$2:T$9999=Blotter!C31)*(Trades!U$2:U$9999=Blotter!B31)*(Trades!W$2:W$9999)*(Trades!V$2:V$9999)*(Trades!V$2:V$9999>0))/SUM((Trades!T$2:T$9999=Blotter!C31)*(Trades!U$2:U$9999=Blotter!B31)*(Trades!V$2:V$9999)*(Trades!V$2:V$9999>0))),SUM((Trades!T$2:T$9999=Blotter!C31)*(Trades!U$2:U$9999=Blotter!B31)*(Trades!W$2:W$9999)*(Trades!V$2:V$9999)*(Trades!V$2:V$9999>0))/SUM((Trades!T$2:T$9999=Blotter!C31)*(Trades!U$2:U$9999=Blotter!B31)*(Trades!V$2:V$9999)*(Trades!V$2:V$9999>0)),0)} -> 0.6825 | Z31: =IF(C$2="Last",IF(ISNUMBER(VLOOKUP(B31,Data_IB!B:O,14,0)),VLOOKUP(B31,Data_IB!B:O,14,0),0),IF(ISNUMBER(VLOOKUP(B31,Data_IB!B:O,13,0)),VLOOKUP(B31,Data_IB!B:O,13,0),0)) -> 0
B32: SOZ3 C2470 | C32: 6 | D32: SI | E32: Commodities | F32: Call | G32: =IF(F32="Futures",VLOOKUP(D32,Multiplier!B:I,8,0),0) -> 0 | H32: -15 | I32: {=SUM((Trades!V$2:V$9999)*(Trades!U$2:U$9999=Blotter!B32)*(Trades!$T$2:T$9999=Blotter!C32))} -> 0 | J32: =VLOOKUP(D32,Multiplier!B:D,2,0) -> 5000 | K32: =L32-N32/(H32*J32) -> 0.181052 | L32: =IF(I32=0,IF(H32>0,X32,Y32),Z32) -> 0.246 | M32: =I32*J32*L32 -> 0 | N32: {=-SUM((Trades!T$2:T$9999=Blotter!C32)*(Trades!U$2:U$9999=Blotter!B32)*(Trades!V$2:V$9999)*(Trades!W$2:W$9999))*J32+SUM((Trades!T$2:T$9999=Blotter!C32)*(Trades!U$2:U$9999=Blotter!B32)*(Trades!X$2:X$9999))+(L32*I32)*J32} -> -4871.1 | O32: =VLOOKUP(D32,Multiplier!B:H,3,0) -> 0.825 | P32: 0.182 | Q32: 1 | R32: =(1-Q32)*P32*J32*H32 -> 0 | S32: =IF(OR(F32="Futures",F32="Stocks"),IF(I32=0,0,IF(I32>0,L32-O32,L32+O32)),0) -> 0 | T32: =IF(S32>0,IF(ISNUMBER(S32/L32-1),S32/L32-1,0),0) -> 0 | U32: =IF(OR(F32="Futures",F32="Stocks"),IF(I32=0,0,IF(I32>0,K32-P32,K32+P32)),0) -> 0 | V32: =IF(U32>0,IF(ISNUMBER(U32/L32-1),U32/L32-1,0),0) -> 0 | X32: {=IF(ISNUMBER(SUM((Trades!T$2:T$9999=Blotter!C32)*(Trades!U$2:U$9999=Blotter!B32)*(Trades!W$2:W$9999)*(Trades!V$2:V$9999)*(Trades!V$2:V$9999<0))/SUM((Trades!T$2:T$9999=Blotter!C32)*(Trades!U$2:U$9999=Blotter!B32)*(Trades!V$2:V$9999)*(Trades!V$2:V$9999<0))),SUM((Trades!T$2:T$9999=Blotter!C32)*(Trades!U$2:U$9999=Blotter!B32)*(Trades!W$2:W$9999)*(Trades!V$2:V$9999)*(Trades!V$2:V$9999<0))/SUM((Trades!T$2:T$9999=Blotter!C32)*(Trades!U$2:U$9999=Blotter!B32)*(Trades!V$2:V$9999)*(Trades!V$2:V$9999<0)),0)} -> 0.182 | Y32: {=IF(ISNUMBER(SUM((Trades!T$2:T$9999=Blotter!C32)*(Trades!U$2:U$9999=Blotter!B32)*(Trades!W$2:W$9999)*(Trades!V$2:V$9999)*(Trades!V$2:V$9999>0))/SUM((Trades!T$2:T$9999=Blotter!C32)*(Trades!U$2:U$9999=Blotter!B32)*(Trades!V$2:V$9999)*(Trades!V$2:V$9999>0))),SUM((Trades!T$2:T$9999=Blotter!C32)*(Trades!U$2:U$9999=Blotter!B32)*(Trades!W$2:W$9999)*(Trades!V$2:V$9999)*(Trades!V$2:V$9999>0))/SUM((Trades!T$2:T$9999=Blotter!C32)*(Trades!U$2:U$9999=Blotter!B32)*(Trades!V$2:V$9999)*(Trades!V$2:V$9999>0)),0)} -> 0.246 | Z32: =IF(C$2="Last",IF(ISNUMBER(VLOOKUP(B32,Data_IB!B:O,14,0)),VLOOKUP(B32,Data_IB!B:O,14,0),0),IF(ISNUMBER(VLOOKUP(B32,Data_IB!B:O,13,0)),VLOOKUP(B32,Data_IB!B:O,13,0),0)) -> 0
B33: SOJ4 C2650 | C33: 6 | D33: SI | E33: Commodities | F33: Call | G33: =IF(F33="Futures",VLOOKUP(D33,Multiplier!B:I,8,0),0) -> 0 | H33: 7 | I33: {=SUM((Trades!V$2:V$9999)*(Trades!U$2:U$9999=Blotter!B33)*(Trades!$T$2:T$9999=Blotter!C33))} -> 0 | J33: =VLOOKUP(D33,Multiplier!B:D,2,0) -> 5000 | K33: =L33-N33/(H33*J33) -> 0.950968 | L33: =IF(I33=0,IF(H33>0,X33,Y33),Z33) -> 0.1 | M33: =I33*J33*L33 -> 0 | N33: {=-SUM((Trades!T$2:T$9999=Blotter!C33)*(Trades!U$2:U$9999=Blotter!B33)*(Trades!V$2:V$9999)*(Trades!W$2:W$9999))*J33+SUM((Trades!T$2:T$9999=Blotter!C33)*(Trades!U$2:U$9999=Blotter!B33)*(Trades!X$2:X$9999))+(L33*I33)*J33} -> -29783.88 | O33: =VLOOKUP(D33,Multiplier!B:H,3,0) -> 0.825 | P33: 0.95 | R33: =(1-Q33)*P33*J33*H33 -> 33250 | S33: =IF(OR(F33="Futures",F33="Stocks"),IF(I33=0,0,IF(I33>0,L33-O33,L33+O33)),0) -> 0 | T33: =IF(S33>0,IF(ISNUMBER(S33/L33-1),S33/L33-1,0),0) -> 0 | U33: =IF(OR(F33="Futures",F33="Stocks"),IF(I33=0,0,IF(I33>0,K33-P33,K33+P33)),0) -> 0 | V33: =IF(U33>0,IF(ISNUMBER(U33/L33-1),U33/L33-1,0),0) -> 0 | X33: {=IF(ISNUMBER(SUM((Trades!T$2:T$9999=Blotter!C33)*(Trades!U$2:U$9999=Blotter!B33)*(Trades!W$2:W$9999)*(Trades!V$2:V$9999)*(Trades!V$2:V$9999<0))/SUM((Trades!T$2:T$9999=Blotter!C33)*(Trades!U$2:U$9999=Blotter!B33)*(Trades!V$2:V$9999)*(Trades!V$2:V$9999<0))),SUM((Trades!T$2:T$9999=Blotter!C33)*(Trades!U$2:U$9999=Blotter!B33)*(Trades!W$2:W$9999)*(Trades!V$2:V$9999)*(Trades!V$2:V$9999<0))/SUM((Trades!T$2:T$9999=Blotter!C33)*(Trades!U$2:U$9999=Blotter!B33)*(Trades!V$2:V$9999)*(Trades!V$2:V$9999<0)),0)} -> 0.1 | Y33: {=IF(ISNUMBER(SUM((Trades!T$2:T$9999=Blotter!C33)*(Trades!U$2:U$9999=Blotter!B33)*(Trades!W$2:W$9999)*(Trades!V$2:V$9999)*(Trades!V$2:V$9999>0))/SUM((Trades!T$2:T$9999=Blotter!C33)*(Trades!U$2:U$9999=Blotter!B33)*(Trades!V$2:V$9999)*(Trades!V$2:V$9999>0))),SUM((Trades!T$2:T$9999=Blotter!C33)*(Trades!U$2:U$9999=Blotter!B33)*(Trades!W$2:W$9999)*(Trades!V$2:V$9999)*(Trades!V$2:V$9999>0))/SUM((Trades!T$2:T$9999=Blotter!C33)*(Trades!U$2:U$9999=Blotter!B33)*(Trades!V$2:V$9999)*(Trades!V$2:V$9999>0)),0)} -> 0.95 | Z33: =IF(C$2="Last",IF(ISNUMBER(VLOOKUP(B33,Data_IB!B:O,14,0)),VLOOKUP(B33,Data_IB!B:O,14,0),0),IF(ISNUMBER(VLOOKUP(B33,Data_IB!B:O,13,0)),VLOOKUP(B33,Data_IB!B:O,13,0),0)) -> 0
B34: SOJ4 C3000 | C34: 6 | D34: SI | E34: Commodities | F34: Call | G34: =IF(F34="Futures",VLOOKUP(D34,Multiplier!B:I,8,0),0) -> 0 | H34: -7 | I34: {=SUM((Trades!V$2:V$9999)*(Trades!U$2:U$9999=Blotter!B34)*(Trades!$T$2:T$9999=Blotter!C34))} -> 0 | J34: =VLOOKUP(D34,Multiplier!B:D,2,0) -> 5000 | K34: =L34-N34/(H34*J34) -> 0.379526 | L34: =IF(I34=0,IF(H34>0,X34,Y34),Z34) -> 0 | M34: =I34*J34*L34 -> 0 | N34: {=-SUM((Trades!T$2:T$9999=Blotter!C34)*(Trades!U$2:U$9999=Blotter!B34)*(Trades!V$2:V$9999)*(Trades!W$2:W$9999))*J34+SUM((Trades!T$2:T$9999=Blotter!C34)*(Trades!U$2:U$9999=Blotter!B34)*(Trades!X$2:X$9999))+(L34*I34)*J34} -> 13283.41 | O34: =VLOOKUP(D34,Multiplier!B:H,3,0) -> 0.825 | P34: 0.38 | R34: =(1-Q34)*P34*J34*H34 -> -13300 | S34: =IF(OR(F34="Futures",F34="Stocks"),IF(I34=0,0,IF(I34>0,L34-O34,L34+O34)),0) -> 0 | T34: =IF(S34>0,IF(ISNUMBER(S34/L34-1),S34/L34-1,0),0) -> 0 | U34: =IF(OR(F34="Futures",F34="Stocks"),IF(I34=0,0,IF(I34>0,K34-P34,K34+P34)),0) -> 0 | V34: =IF(U34>0,IF(ISNUMBER(U34/L34-1),U34/L34-1,0),0) -> 0 | X34: {=IF(ISNUMBER(SUM((Trades!T$2:T$9999=Blotter!C34)*(Trades!U$2:U$9999=Blotter!B34)*(Trades!W$2:W$9999)*(Trades!V$2:V$9999)*(Trades!V$2:V$9999<0))/SUM((Trades!T$2:T$9999=Blotter!C34)*(Trades!U$2:U$9999=Blotter!B34)*(Trades!V$2:V$9999)*(Trades!V$2:V$9999<0))),SUM((Trades!T$2:T$9999=Blotter!C34)*(Trades!U$2:U$9999=Blotter!B34)*(Trades!W$2:W$9999)*(Trades!V$2:V$9999)*(Trades!V$2:V$9999<0))/SUM((Trades!T$2:T$9999=Blotter!C34)*(Trades!U$2:U$9999=Blotter!B34)*(Trades!V$2:V$9999)*(Trades!V$2:V$9999<0)),0)} -> 0.38 | Y34: {=IF(ISNUMBER(SUM((Trades!T$2:T$9999=Blotter!C34)*(Trades!U$2:U$9999=Blotter!B34)*(Trades!W$2:W$9999)*(Trades!V$2:V$9999)*(Trades!V$2:V$9999>0))/SUM((Trades!T$2:T$9999=Blotter!C34)*(Trades!U$2:U$9999=Blotter!B34)*(Trades!V$2:V$9999)*(Trades!V$2:V$9999>0))),SUM((Trades!T$2:T$9999=Blotter!C34)*(Trades!U$2:U$9999=Blotter!B34)*(Trades!W$2:W$9999)*(Trades!V$2:V$9999)*(Trades!V$2:V$9999>0))/SUM((Trades!T$2:T$9999=Blotter!C34)*(Trades!U$2:U$9999=Blotter!B34)*(Trades!V$2:V$9999)*(Trades!V$2:V$9999>0)),0)} -> 0 | Z34: =IF(C$2="Last",IF(ISNUMBER(VLOOKUP(B34,Data_IB!B:O,14,0)),VLOOKUP(B34,Data_IB!B:O,14,0),0),IF(ISNUMBER(VLOOKUP(B34,Data_IB!B:O,13,0)),VLOOKUP(B34,Data_IB!B:O,13,0),0)) -> 0
B35: HGN3 | C35: 8 | D35: HG | E35: Commodities | F35: Futures | G35: =IF(F35="Futures",VLOOKUP(D35,Multiplier!B:I,8,0),0) -> 6 | H35: 4 | I35: {=SUM((Trades!V$2:V$9999)*(Trades!U$2:U$9999=Blotter!B35)*(Trades!$T$2:T$9999=Blotter!C35))} -> 0 | J35: =VLOOKUP(D35,Multiplier!B:D,2,0) -> 25000 | K35: =L35-N35/(H35*J35) -> 3.7413737 | L35: =IF(I35=0,IF(H35>0,X35,Y35),Z35) -> 3.7753333 | M35: =I35*J35*L35 -> 0 | N35: {=-SUM((Trades!T$2:T$9999=Blotter!C35)*(Trades!U$2:U$9999=Blotter!B35)*(Trades!V$2:V$9999)*(Trades!W$2:W$9999))*J35+SUM((Trades!T$2:T$9999=Blotter!C35)*(Trades!U$2:U$9999=Blotter!B35)*(Trades!X$2:X$9999))+(L35*I35)*J35} -> 3395.96 | O35: =VLOOKUP(D35,Multiplier!B:H,3,0) -> 0.0708 | P35: 0.09 | Q35: 1 | R35: =(1-Q35)*P35*J35*H35 -> 0 | S35: =IF(OR(F35="Futures",F35="Stocks"),IF(I35=0,0,IF(I35>0,L35-O35,L35+O35)),0) -> 0 | T35: =IF(S35>0,IF(ISNUMBER(S35/L35-1),S35/L35-1,0),0) -> 0 | U35: =IF(OR(F35="Futures",F35="Stocks"),IF(I35=0,0,IF(I35>0,K35-P35,K35+P35)),0) -> 0 | V35: =IF(U35>0,IF(ISNUMBER(U35/L35-1),U35/L35-1,0),0) -> 0 | X35: {=IF(ISNUMBER(SUM((Trades!T$2:T$9999=Blotter!C35)*(Trades!U$2:U$9999=Blotter!B35)*(Trades!W$2:W$9999)*(Trades!V$2:V$9999)*(Trades!V$2:V$9999<0))/SUM((Trades!T$2:T$9999=Blotter!C35)*(Trades!U$2:U$9999=Blotter!B35)*(Trades!V$2:V$9999)*(Trades!V$2:V$9999<0))),SUM((Trades!T$2:T$9999=Blotter!C35)*(Trades!U$2:U$9999=Blotter!B35)*(Trades!W$2:W$9999)*(Trades!V$2:V$9999)*(Trades!V$2:V$9999<0))/SUM((Trades!T$2:T$9999=Blotter!C35)*(Trades!U$2:U$9999=Blotter!B35)*(Trades!V$2:V$9999)*(Trades!V$2:V$9999<0)),0)} -> 3.7753333 | Y35: {=IF(ISNUMBER(SUM((Trades!T$2:T$9999=Blotter!C35)*(Trades!U$2:U$9999=Blotter!B35)*(Trades!W$2:W$9999)*(Trades!V$2:V$9999)*(Trades!V$2:V$9999>0))/SUM((Trades!T$2:T$9999=Blotter!C35)*(Trades!U$2:U$9999=Blotter!B35)*(Trades!V$2:V$9999)*(Trades!V$2:V$9999>0))),SUM((Trades!T$2:T$9999=Blotter!C35)*(Trades!U$2:U$9999=Blotter!B35)*(Trades!W$2:W$9999)*(Trades!V$2:V$9999)*(Trades!V$2:V$9999>0))/SUM((Trades!T$2:T$9999=Blotter!C35)*(Trades!U$2:U$9999=Blotter!B35)*(Trades!V$2:V$9999)*(Trades!V$2:V$9999>0)),0)} -> 3.7525 | Z35: =IF(C$2="Last",IF(ISNUMBER(VLOOKUP(B35,Data_IB!B:O,14,0)),VLOOKUP(B35,Data_IB!B:O,14,0),0),IF(ISNUMBER(VLOOKUP(B35,Data_IB!B:O,13,0)),VLOOKUP(B35,Data_IB!B:O,13,0),0)) -> 0
B36: HGU3 | C36: 8 | D36: HG | E36: Commodities | F36: Futures | G36: =IF(F36="Futures",VLOOKUP(D36,Multiplier!B:I,8,0),0) -> 6 | H36: 4 | I36: {=SUM((Trades!V$2:V$9999)*(Trades!U$2:U$9999=Blotter!B36)*(Trades!$T$2:T$9999=Blotter!C36))} -> 0 | J36: =VLOOKUP(D36,Multiplier!B:D,2,0) -> 25000 | K36: =L36-N36/(H36*J36) -> 3.5744981 | L36: =IF(I36=0,IF(H36>0,X36,Y36),Z36) -> 3.7596429 | M36: =I36*J36*L36 -> 0 | N36: {=-SUM((Trades!T$2:T$9999=Blotter!C36)*(Trades!U$2:U$9999=Blotter!B36)*(Trades!V$2:V$9999)*(Trades!W$2:W$9999))*J36+SUM((Trades!T$2:T$9999=Blotter!C36)*(Trades!U$2:U$9999=Blotter!B36)*(Trades!X$2:X$9999))+(L36*I36)*J36} -> 18514.48 | O36: =VLOOKUP(D36,Multiplier!B:H,3,0) -> 0.0708 | P36: 0.09 | R36: =(1-Q36)*P36*J36*H36 -> 9000 | S36: =IF(OR(F36="Futures",F36="Stocks"),IF(I36=0,0,IF(I36>0,L36-O36,L36+O36)),0) -> 0 | T36: =IF(S36>0,IF(ISNUMBER(S36/L36-1),S36/L36-1,0),0) -> 0 | U36: =IF(OR(F36="Futures",F36="Stocks"),IF(I36=0,0,IF(I36>0,K36-P36,K36+P36)),0) -> 0 | V36: =IF(U36>0,IF(ISNUMBER(U36/L36-1),U36/L36-1,0),0) -> 0 | X36: {=IF(ISNUMBER(SUM((Trades!T$2:T$9999=Blotter!C36)*(Trades!U$2:U$9999=Blotter!B36)*(Trades!W$2:W$9999)*(Trades!V$2:V$9999)*(Trades!V$2:V$9999<0))/SUM((Trades!T$2:T$9999=Blotter!C36)*(Trades!U$2:U$9999=Blotter!B36)*(Trades!V$2:V$9999)*(Trades!V$2:V$9999<0))),SUM((Trades!T$2:T$9999=Blotter!C36)*(Trades!U$2:U$9999=Blotter!B36)*(Trades!W$2:W$9999)*(Trades!V$2:V$9999)*(Trades!V$2:V$9999<0))/SUM((Trades!T$2:T$9999=Blotter!C36)*(Trades!U$2:U$9999=Blotter!B36)*(Trades!V$2:V$9999)*(Trades!V$2:V$9999<0)),0)} -> 3.7596429 | Y36: {=IF(ISNUMBER(SUM((Trades!T$2:T$9999=Blotter!C36)*(Trades!U$2:U$9999=Blotter!B36)*(Trades!W$2:W$9999)*(Trades!V$2:V$9999)*(Trades!V$2:V$9999>0))/SUM((Trades!T$2:T$9999=Blotter!C36)*(Trades!U$2:U$9999=Blotter!B36)*(Trades!V$2:V$9999)*(Trades!V$2:V$9999>0))),SUM((Trades!T$2:T$9999=Blotter!C36)*(Trades!U$2:U$9999=Blotter!B36)*(Trades!W$2:W$9999)*(Trades!V$2:V$9999)*(Trades!V$2:V$9999>0))/SUM((Trades!T$2:T$9999=Blotter!C36)*(Trades!U$2:U$9999=Blotter!B36)*(Trades!V$2:V$9999)*(Trades!V$2:V$9999>0)),0)} -> 3.733 | Z36: =IF(C$2="Last",IF(ISNUMBER(VLOOKUP(B36,Data_IB!B:O,14,0)),VLOOKUP(B36,Data_IB!B:O,14,0),0),IF(ISNUMBER(VLOOKUP(B36,Data_IB!B:O,13,0)),VLOOKUP(B36,Data_IB!B:O,13,0),0)) -> 0
B37: INDA 231215C00044000 | C37: 9 | D37: INDA | E37: Equity | F37: Call | G37: =IF(F37="Futures",VLOOKUP(D37,Multiplier!B:I,8,0),0) -> 0 | H37: 70 | I37: {=SUM((Trades!V$2:V$9999)*(Trades!U$2:U$9999=Blotter!B37)*(Trades!$T$2:T$9999=Blotter!C37))} -> 0 | J37: =VLOOKUP(D37,Multiplier!B:D,2,0) -> 100 | K37: =L37-N37/(H37*J37) -> 1.3962474 | L37: =IF(I37=0,IF(H37>0,X37,Y37),Z37) -> 2.325 | M37: =I37*J37*L37 -> 0 | N37: {=-SUM((Trades!T$2:T$9999=Blotter!C37)*(Trades!U$2:U$9999=Blotter!B37)*(Trades!V$2:V$9999)*(Trades!W$2:W$9999))*J37+SUM((Trades!T$2:T$9999=Blotter!C37)*(Trades!U$2:U$9999=Blotter!B37)*(Trades!X$2:X$9999))+(L37*I37)*J37} -> 6501.268 | O37: =VLOOKUP(D37,Multiplier!B:H,3,0) -> 0.3075 | P37: 1.4 | R37: =(1-Q37)*P37*J37*H37 -> 9800 | S37: =IF(OR(F37="Futures",F37="Stocks"),IF(I37=0,0,IF(I37>0,L37-O37,L37+O37)),0) -> 0 | T37: =IF(S37>0,IF(ISNUMBER(S37/L37-1),S37/L37-1,0),0) -> 0 | U37: =IF(OR(F37="Futures",F37="Stocks"),IF(I37=0,0,IF(I37>0,K37-P37,K37+P37)),0) -> 0 | V37: =IF(U37>0,IF(ISNUMBER(U37/L37-1),U37/L37-1,0),0) -> 0 | X37: {=IF(ISNUMBER(SUM((Trades!T$2:T$9999=Blotter!C37)*(Trades!U$2:U$9999=Blotter!B37)*(Trades!W$2:W$9999)*(Trades!V$2:V$9999)*(Trades!V$2:V$9999<0))/SUM((Trades!T$2:T$9999=Blotter!C37)*(Trades!U$2:U$9999=Blotter!B37)*(Trades!V$2:V$9999)*(Trades!V$2:V$9999<0))),SUM((Trades!T$2:T$9999=Blotter!C37)*(Trades!U$2:U$9999=Blotter!B37)*(Trades!W$2:W$9999)*(Trades!V$2:V$9999)*(Trades!V$2:V$9999<0))/SUM((Trades!T$2:T$9999=Blotter!C37)*(Trades!U$2:U$9999=Blotter!B37)*(Trades!V$2:V$9999)*(Trades!V$2:V$9999<0)),0)} -> 2.325 | Y37: {=IF(ISNUMBER(SUM((Trades!T$2:T$9999=Blotter!C37)*(Trades!U$2:U$9999=Blotter!B37)*(Trades!W$2:W$9999)*(Trades!V$2:V$9999)*(Trades!V$2:V$9999>0))/SUM((Trades!T$2:T$9999=Blotter!C37)*(Trades!U$2:U$9999=Blotter!B37)*(Trades!V$2:V$9999)*(Trades!V$2:V$9999>0))),SUM((Trades!T$2:T$9999=Blotter!C37)*(Trades!U$2:U$9999=Blotter!B37)*(Trades!W$2:W$9999)*(Trades!V$2:V$9999)*(Trades!V$2:V$9999>0))/SUM((Trades!T$2:T$9999=Blotter!C37)*(Trades!U$2:U$9999=Blotter!B37)*(Trades!V$2:V$9999)*(Trades!V$2:V$9999>0)),0)} -> 1.3985714 | Z37: =IF(C$2="Last",IF(ISNUMBER(VLOOKUP(B37,Data_IB!B:O,14,0)),VLOOKUP(B37,Data_IB!B:O,14,0),0),IF(ISNUMBER(VLOOKUP(B37,Data_IB!B:O,13,0)),VLOOKUP(B37,Data_IB!B:O,13,0),0)) -> 0
B38: SPXW 230622P04340000 | C38: 10 | D38: SPX | E38: Equity | F38: Put | G38: =IF(F38="Futures",VLOOKUP(D38,Multiplier!B:I,8,0),0) -> 0 | H38: 4 | I38: {=SUM((Trades!V$2:V$9999)*(Trades!U$2:U$9999=Blotter!B38)*(Trades!$T$2:T$9999=Blotter!C38))} -> 0 | J38: =VLOOKUP(D38,Multiplier!B:D,2,0) -> 100 | K38: =L38-N38/(H38*J38) -> 11.505413 | L38: =IF(I38=0,IF(H38>0,X38,Y38),Z38) -> 8.0666667 | M38: =I38*J38*L38 -> 0 | N38: {=-SUM((Trades!T$2:T$9999=Blotter!C38)*(Trades!U$2:U$9999=Blotter!B38)*(Trades!V$2:V$9999)*(Trades!W$2:W$9999))*J38+SUM((Trades!T$2:T$9999=Blotter!C38)*(Trades!U$2:U$9999=Blotter!B38)*(Trades!X$2:X$9999))+(L38*I38)*J38} -> -1375.4986 | O38: =VLOOKUP(D38,Multiplier!B:H,3,0) -> 42 | P38: 8.5 | R38: =(1-Q38)*P38*J38*H38 -> 3400 | S38: =IF(OR(F38="Futures",F38="Stocks"),IF(I38=0,0,IF(I38>0,L38-O38,L38+O38)),0) -> 0 | T38: =IF(S38>0,IF(ISNUMBER(S38/L38-1),S38/L38-1,0),0) -> 0 | U38: =IF(OR(F38="Futures",F38="Stocks"),IF(I38=0,0,IF(I38>0,K38-P38,K38+P38)),0) -> 0 | V38: =IF(U38>0,IF(ISNUMBER(U38/L38-1),U38/L38-1,0),0) -> 0 | X38: {=IF(ISNUMBER(SUM((Trades!T$2:T$9999=Blotter!C38)*(Trades!U$2:U$9999=Blotter!B38)*(Trades!W$2:W$9999)*(Trades!V$2:V$9999)*(Trades!V$2:V$9999<0))/SUM((Trades!T$2:T$9999=Blotter!C38)*(Trades!U$2:U$9999=Blotter!B38)*(Trades!V$2:V$9999)*(Trades!V$2:V$9999<0))),SUM((Trades!T$2:T$9999=Blotter!C38)*(Trades!U$2:U$9999=Blotter!B38)*(Trades!W$2:W$9999)*(Trades!V$2:V$9999)*(Trades!V$2:V$9999<0))/SUM((Trades!T$2:T$9999=Blotter!C38)*(Trades!U$2:U$9999=Blotter!B38)*(Trades!V$2:V$9999)*(Trades!V$2:V$9999<0)),0)} -> 8.0666667 | Y38: {=IF(ISNUMBER(SUM((Trades!T$2:T$9999=Blotter!C38)*(Trades!U$2:U$9999=Blotter!B38)*(Trades!W$2:W$9999)*(Trades!V$2:V$9999)*(Trades!V$2:V$9999>0))/SUM((Trades!T$2:T$9999=Blotter!C38)*(Trades!U$2:U$9999=Blotter!B38)*(Trades!V$2:V$9999)*(Trades!V$2:V$9999>0))),SUM((Trades!T$2:T$9999=Blotter!C38)*(Trades!U$2:U$9999=Blotter!B38)*(Trades!W$2:W$9999)*(Trades!V$2:V$9999)*(Trades!V$2:V$9999>0))/SUM((Trades!T$2:T$9999=Blotter!C38)*(Trades!U$2:U$9999=Blotter!B38)*(Trades!V$2:V$9999)*(Trades!V$2:V$9999>0)),0)} -> 10.333333 | Z38: =IF(C$2="Last",IF(ISNUMBER(VLOOKUP(B38,Data_IB!B:O,14,0)),VLOOKUP(B38,Data_IB!B:O,14,0),0),IF(ISNUMBER(VLOOKUP(B38,Data_IB!B:O,13,0)),VLOOKUP(B38,Data_IB!B:O,13,0),0)) -> 0
B39: RBQ3 | C39: 11 | D39: RB | E39: Commodities | F39: Futures | G39: =IF(F39="Futures",VLOOKUP(D39,Multiplier!B:I,8,0),0) -> 3 | H39: 2 | I39: {=SUM((Trades!V$2:V$9999)*(Trades!U$2:U$9999=Blotter!B39)*(Trades!$T$2:T$9999=Blotter!C39))} -> 0 | J39: =VLOOKUP(D39,Multiplier!B:D,2,0) -> 42000 | K39: =L39-N39/(H39*J39) -> 2.5053707 | L39: =IF(I39=0,IF(H39>0,X39,Y39),Z39) -> 2.5385 | M39: =I39*J39*L39 -> 0 | N39: {=-SUM((Trades!T$2:T$9999=Blotter!C39)*(Trades!U$2:U$9999=Blotter!B39)*(Trades!V$2:V$9999)*(Trades!W$2:W$9999))*J39+SUM((Trades!T$2:T$9999=Blotter!C39)*(Trades!U$2:U$9999=Blotter!B39)*(Trades!X$2:X$9999))+(L39*I39)*J39} -> 2782.86 | O39: =VLOOKUP(D39,Multiplier!B:H,3,0) -> 0.0725 | P39: 0.1 | R39: =(1-Q39)*P39*J39*H39 -> 8400 | S39: =IF(OR(F39="Futures",F39="Stocks"),IF(I39=0,0,IF(I39>0,L39-O39,L39+O39)),0) -> 0 | T39: =IF(S39>0,IF(ISNUMBER(S39/L39-1),S39/L39-1,0),0) -> 0 | U39: =IF(OR(F39="Futures",F39="Stocks"),IF(I39=0,0,IF(I39>0,K39-P39,K39+P39)),0) -> 0 | V39: =IF(U39>0,IF(ISNUMBER(U39/L39-1),U39/L39-1,0),0) -> 0 | X39: {=IF(ISNUMBER(SUM((Trades!T$2:T$9999=Blotter!C39)*(Trades!U$2:U$9999=Blotter!B39)*(Trades!W$2:W$9999)*(Trades!V$2:V$9999)*(Trades!V$2:V$9999<0))/SUM((Trades!T$2:T$9999=Blotter!C39)*(Trades!U$2:U$9999=Blotter!B39)*(Trades!V$2:V$9999)*(Trades!V$2:V$9999<0))),SUM((Trades!T$2:T$9999=Blotter!C39)*(Trades!U$2:U$9999=Blotter!B39)*(Trades!W$2:W$9999)*(Trades!V$2:V$9999)*(Trades!V$2:V$9999<0))/SUM((Trades!T$2:T$9999=Blotter!C39)*(Trades!U$2:U$9999=Blotter!B39)*(Trades!V$2:V$9999)*(Trades!V$2:V$9999<0)),0)} -> 2.5385 | Y39: {=IF(ISNUMBER(SUM((Trades!T$2:T$9999=Blotter!C39)*(Trades!U$2:U$9999=Blotter!B39)*(Trades!W$2:W$9999)*(Trades!V$2:V$9999)*(Trades!V$2:V$9999>0))/SUM((Trades!T$2:T$9999=Blotter!C39)*(Trades!U$2:U$9999=Blotter!B39)*(Trades!V$2:V$9999)*(Trades!V$2:V$9999>0))),SUM((Trades!T$2:T$9999=Blotter!C39)*(Trades!U$2:U$9999=Blotter!B39)*(Trades!W$2:W$9999)*(Trades!V$2:V$9999)*(Trades!V$2:V$9999>0))/SUM((Trades!T$2:T$9999=Blotter!C39)*(Trades!U$2:U$9999=Blotter!B39)*(Trades!V$2:V$9999)*(Trades!V$2:V$9999>0)),0)} -> 2.5323636 | Z39: =IF(C$2="Last",IF(ISNUMBER(VLOOKUP(B39,Data_IB!B:O,14,0)),VLOOKUP(B39,Data_IB!B:O,14,0),0),IF(ISNUMBER(VLOOKUP(B39,Data_IB!B:O,13,0)),VLOOKUP(B39,Data_IB!B:O,13,0),0)) -> 0
B40: C OZC DEC 23 6000 | C40: 13 | D40: ZC | E40: Commodities | F40: Call | G40: =IF(F40="Futures",VLOOKUP(D40,Multiplier!B:I,8,0),0) -> 0 | H40: 12 | I40: {=SUM((Trades!V$2:V$9999)*(Trades!U$2:U$9999=Blotter!B40)*(Trades!$T$2:T$9999=Blotter!C40))} -> 0 | J40: =VLOOKUP(D40,Multiplier!B:D,2,0) -> 50 | K40: =L40-N40/(H40*J40) -> 8.5792 | L40: =IF(I40=0,IF(H40>0,X40,Y40),Z40) -> 8.6666667 | M40: =I40*J40*L40 -> 0 | N40: {=-SUM((Trades!T$2:T$9999=Blotter!C40)*(Trades!U$2:U$9999=Blotter!B40)*(Trades!V$2:V$9999)*(Trades!W$2:W$9999))*J40+SUM((Trades!T$2:T$9999=Blotter!C40)*(Trades!U$2:U$9999=Blotter!B40)*(Trades!X$2:X$9999))+(L40*I40)*J40} -> 52.48 | O40: =VLOOKUP(D40,Multiplier!B:H,3,0) -> 8.25 | P40: 8.5 | R40: =(1-Q40)*P40*J40*H40 -> 5100 | S40: =IF(OR(F40="Futures",F40="Stocks"),IF(I40=0,0,IF(I40>0,L40-O40,L40+O40)),0) -> 0 | T40: =IF(S40>0,IF(ISNUMBER(S40/L40-1),S40/L40-1,0),0) -> 0 | U40: =IF(OR(F40="Futures",F40="Stocks"),IF(I40=0,0,IF(I40>0,K40-P40,K40+P40)),0) -> 0 | V40: =IF(U40>0,IF(ISNUMBER(U40/L40-1),U40/L40-1,0),0) -> 0 | X40: {=IF(ISNUMBER(SUM((Trades!T$2:T$9999=Blotter!C40)*(Trades!U$2:U$9999=Blotter!B40)*(Trades!W$2:W$9999)*(Trades!V$2:V$9999)*(Trades!V$2:V$9999<0))/SUM((Trades!T$2:T$9999=Blotter!C40)*(Trades!U$2:U$9999=Blotter!B40)*(Trades!V$2:V$9999)*(Trades!V$2:V$9999<0))),SUM((Trades!T$2:T$9999=Blotter!C40)*(Trades!U$2:U$9999=Blotter!B40)*(Trades!W$2:W$9999)*(Trades!V$2:V$9999)*(Trades!V$2:V$9999<0))/SUM((Trades!T$2:T$9999=Blotter!C40)*(Trades!U$2:U$9999=Blotter!B40)*(Trades!V$2:V$9999)*(Trades!V$2:V$9999<0)),0)} -> 8.6666667 | Y40: {=IF(ISNUMBER(SUM((Trades!T$2:T$9999=Blotter!C40)*(Trades!U$2:U$9999=Blotter!B40)*(Trades!W$2:W$9999)*(Trades!V$2:V$9999)*(Trades!V$2:V$9999>0))/SUM((Trades!T$2:T$9999=Blotter!C40)*(Trades!U$2:U$9999=Blotter!B40)*(Trades!V$2:V$9999)*(Trades!V$2:V$9999>0))),SUM((Trades!T$2:T$9999=Blotter!C40)*(Trades!U$2:U$9999=Blotter!B40)*(Trades!W$2:W$9999)*(Trades!V$2:V$9999)*(Trades!V$2:V$9999>0))/SUM((Trades!T$2:T$9999=Blotter!C40)*(Trades!U$2:U$9999=Blotter!B40)*(Trades!V$2:V$9999)*(Trades!V$2:V$9999>0)),0)} -> 8.5 | Z40: =IF(C$2="Last",IF(ISNUMBER(VLOOKUP(B40,Data_IB!B:O,14,0)),VLOOKUP(B40,Data_IB!B:O,14,0),0),IF(ISNUMBER(VLOOKUP(B40,Data_IB!B:O,13,0)),VLOOKUP(B40,Data_IB!B:O,13,0),0)) -> 0
B41: ZCU3 | C41: 13 | D41: ZC | E41: Commodities | F41: Futures | G41: =IF(F41="Futures",VLOOKUP(D41,Multiplier!B:I,8,0),0) -> 24 | H41: 4 | I41: {=SUM((Trades!V$2:V$9999)*(Trades!U$2:U$9999=Blotter!B41)*(Trades!$T$2:T$9999=Blotter!C41))} -> 0 | J41: =VLOOKUP(D41,Multiplier!B:D,2,0) -> 50 | K41: =L41-N41/(H41*J41) -> 483.6188 | L41: =IF(I41=0,IF(H41>0,X41,Y41),Z41) -> 538 | M41: =I41*J41*L41 -> 0 | N41: {=-SUM((Trades!T$2:T$9999=Blotter!C41)*(Trades!U$2:U$9999=Blotter!B41)*(Trades!V$2:V$9999)*(Trades!W$2:W$9999))*J41+SUM((Trades!T$2:T$9999=Blotter!C41)*(Trades!U$2:U$9999=Blotter!B41)*(Trades!X$2:X$9999))+(L41*I41)*J41} -> 10876.24 | O41: =VLOOKUP(D41,Multiplier!B:H,3,0) -> 8.25 | P41: 13.5 | Q41: 1 | R41: =(1-Q41)*P41*J41*H41 -> 0 | S41: =IF(OR(F41="Futures",F41="Stocks"),IF(I41=0,0,IF(I41>0,L41-O41,L41+O41)),0) -> 0 | T41: =IF(S41>0,IF(ISNUMBER(S41/L41-1),S41/L41-1,0),0) -> 0 | U41: =IF(OR(F41="Futures",F41="Stocks"),IF(I41=0,0,IF(I41>0,K41-P41,K41+P41)),0) -> 0 | V41: =IF(U41>0,IF(ISNUMBER(U41/L41-1),U41/L41-1,0),0) -> 0 | X41: {=IF(ISNUMBER(SUM((Trades!T$2:T$9999=Blotter!C41)*(Trades!U$2:U$9999=Blotter!B41)*(Trades!W$2:W$9999)*(Trades!V$2:V$9999)*(Trades!V$2:V$9999<0))/SUM((Trades!T$2:T$9999=Blotter!C41)*(Trades!U$2:U$9999=Blotter!B41)*(Trades!V$2:V$9999)*(Trades!V$2:V$9999<0))),SUM((Trades!T$2:T$9999=Blotter!C41)*(Trades!U$2:U$9999=Blotter!B41)*(Trades!W$2:W$9999)*(Trades!V$2:V$9999)*(Trades!V$2:V$9999<0))/SUM((Trades!T$2:T$9999=Blotter!C41)*(Trades!U$2:U$9999=Blotter!B41)*(Trades!V$2:V$9999)*(Trades!V$2:V$9999<0)),0)} -> 538 | Y41: {=IF(ISNUMBER(SUM((Trades!T$2:T$9999=Blotter!C41)*(Trades!U$2:U$9999=Blotter!B41)*(Trades!W$2:W$9999)*(Trades!V$2:V$9999)*(Trades!V$2:V$9999>0))/SUM((Trades!T$2:T$9999=Blotter!C41)*(Trades!U$2:U$9999=Blotter!B41)*(Trades!V$2:V$9999)*(Trades!V$2:V$9999>0))),SUM((Trades!T$2:T$9999=Blotter!C41)*(Trades!U$2:U$9999=Blotter!B41)*(Trades!W$2:W$9999)*(Trades!V$2:V$9999)*(Trades!V$2:V$9999>0))/SUM((Trades!T$2:T$9999=Blotter!C41)*(Trades!U$2:U$9999=Blotter!B41)*(Trades!V$2:V$9999)*(Trades!V$2:V$9999>0)),0)} -> 483.5 | Z41: =IF(C$2="Last",IF(ISNUMBER(VLOOKUP(B41,Data_IB!B:O,14,0)),VLOOKUP(B41,Data_IB!B:O,14,0),0),IF(ISNUMBER(VLOOKUP(B41,Data_IB!B:O,13,0)),VLOOKUP(B41,Data_IB!B:O,13,0),0)) -> 0
B42: ZCZ3 | C42: 13 | D42: ZC | E42: Commodities | F42: Futures | G42: =IF(F42="Futures",VLOOKUP(D42,Multiplier!B:I,8,0),0) -> 24 | H42: 4 | I42: {=SUM((Trades!V$2:V$9999)*(Trades!U$2:U$9999=Blotter!B42)*(Trades!$T$2:T$9999=Blotter!C42))} -> 0 | J42: =VLOOKUP(D42,Multiplier!B:D,2,0) -> 50 | K42: =L42-N42/(H42*J42) -> 532.1188 | L42: =IF(I42=0,IF(H42>0,X42,Y42),Z42) -> 552 | M42: =I42*J42*L42 -> 0 | N42: {=-SUM((Trades!T$2:T$9999=Blotter!C42)*(Trades!U$2:U$9999=Blotter!B42)*(Trades!V$2:V$9999)*(Trades!W$2:W$9999))*J42+SUM((Trades!T$2:T$9999=Blotter!C42)*(Trades!U$2:U$9999=Blotter!B42)*(Trades!X$2:X$9999))+(L42*I42)*J42} -> 3976.24 | O42: =VLOOKUP(D42,Multiplier!B:H,3,0) -> 8.25 | P42: 13.5 | R42: =(1-Q42)*P42*J42*H42 -> 2700 | S42: =IF(OR(F42="Futures",F42="Stocks"),IF(I42=0,0,IF(I42>0,L42-O42,L42+O42)),0) -> 0 | T42: =IF(S42>0,IF(ISNUMBER(S42/L42-1),S42/L42-1,0),0) -> 0 | U42: =IF(OR(F42="Futures",F42="Stocks"),IF(I42=0,0,IF(I42>0,K42-P42,K42+P42)),0) -> 0 | V42: =IF(U42>0,IF(ISNUMBER(U42/L42-1),U42/L42-1,0),0) -> 0 | X42: {=IF(ISNUMBER(SUM((Trades!T$2:T$9999=Blotter!C42)*(Trades!U$2:U$9999=Blotter!B42)*(Trades!W$2:W$9999)*(Trades!V$2:V$9999)*(Trades!V$2:V$9999<0))/SUM((Trades!T$2:T$9999=Blotter!C42)*(Trades!U$2:U$9999=Blotter!B42)*(Trades!V$2:V$9999)*(Trades!V$2:V$9999<0))),SUM((Trades!T$2:T$9999=Blotter!C42)*(Trades!U$2:U$9999=Blotter!B42)*(Trades!W$2:W$9999)*(Trades!V$2:V$9999)*(Trades!V$2:V$9999<0))/SUM((Trades!T$2:T$9999=Blotter!C42)*(Trades!U$2:U$9999=Blotter!B42)*(Trades!V$2:V$9999)*(Trades!V$2:V$9999<0)),0)} -> 552 | Y42: {=IF(ISNUMBER(SUM((Trades!T$2:T$9999=Blotter!C42)*(Trades!U$2:U$9999=Blotter!B42)*(Trades!W$2:W$9999)*(Trades!V$2:V$9999)*(Trades!V$2:V$9999>0))/SUM((Trades!T$2:T$9999=Blotter!C42)*(Trades!U$2:U$9999=Blotter!B42)*(Trades!V$2:V$9999)*(Trades!V$2:V$9999>0))),SUM((Trades!T$2:T$9999=Blotter!C42)*(Trades!U$2:U$9999=Blotter!B42)*(Trades!W$2:W$9999)*(Trades!V$2:V$9999)*(Trades!V$2:V$9999>0))/SUM((Trades!T$2:T$9999=Blotter!C42)*(Trades!U$2:U$9999=Blotter!B42)*(Trades!V$2:V$9999)*(Trades!V$2:V$9999>0)),0)} -> 532 | Z42: =IF(C$2="Last",IF(ISNUMBER(VLOOKUP(B42,Data_IB!B:O,14,0)),VLOOKUP(B42,Data_IB!B:O,14,0),0),IF(ISNUMBER(VLOOKUP(B42,Data_IB!B:O,13,0)),VLOOKUP(B42,Data_IB!B:O,13,0),0)) -> 0
B43: SBV3 | C43: 14 | D43: SB | E43: Commodities | F43: Futures | G43: =IF(F43="Futures",VLOOKUP(D43,Multiplier!B:I,8,0),0) -> 10 | H43: 14 | I43: {=SUM((Trades!V$2:V$9999)*(Trades!U$2:U$9999=Blotter!B43)*(Trades!$T$2:T$9999=Blotter!C43))} -> 0 | J43: =VLOOKUP(D43,Multiplier!B:D,2,0) -> 1120 | K43: =L43-N43/(H43*J43) -> 23.303107 | L43: =IF(I43=0,IF(H43>0,X43,Y43),Z43) -> 24.1875 | M43: =I43*J43*L43 -> 0 | N43: {=-SUM((Trades!T$2:T$9999=Blotter!C43)*(Trades!U$2:U$9999=Blotter!B43)*(Trades!V$2:V$9999)*(Trades!W$2:W$9999))*J43+SUM((Trades!T$2:T$9999=Blotter!C43)*(Trades!U$2:U$9999=Blotter!B43)*(Trades!X$2:X$9999))+(L43*I43)*J43} -> 13867.28 | O43: =VLOOKUP(D43,Multiplier!B:H,3,0) -> 0.89 | P43: 0.63 | R43: =(1-Q43)*P43*J43*H43 -> 9878.4 | S43: =IF(OR(F43="Futures",F43="Stocks"),IF(I43=0,0,IF(I43>0,L43-O43,L43+O43)),0) -> 0 | T43: =IF(S43>0,IF(ISNUMBER(S43/L43-1),S43/L43-1,0),0) -> 0 | U43: =IF(OR(F43="Futures",F43="Stocks"),IF(I43=0,0,IF(I43>0,K43-P43,K43+P43)),0) -> 0 | V43: =IF(U43>0,IF(ISNUMBER(U43/L43-1),U43/L43-1,0),0) -> 0 | X43: {=IF(ISNUMBER(SUM((Trades!T$2:T$9999=Blotter!C43)*(Trades!U$2:U$9999=Blotter!B43)*(Trades!W$2:W$9999)*(Trades!V$2:V$9999)*(Trades!V$2:V$9999<0))/SUM((Trades!T$2:T$9999=Blotter!C43)*(Trades!U$2:U$9999=Blotter!B43)*(Trades!V$2:V$9999)*(Trades!V$2:V$9999<0))),SUM((Trades!T$2:T$9999=Blotter!C43)*(Trades!U$2:U$9999=Blotter!B43)*(Trades!W$2:W$9999)*(Trades!V$2:V$9999)*(Trades!V$2:V$9999<0))/SUM((Trades!T$2:T$9999=Blotter!C43)*(Trades!U$2:U$9999=Blotter!B43)*(Trades!V$2:V$9999)*(Trades!V$2:V$9999<0)),0)} -> 24.1875 | Y43: {=IF(ISNUMBER(SUM((Trades!T$2:T$9999=Blotter!C43)*(Trades!U$2:U$9999=Blotter!B43)*(Trades!W$2:W$9999)*(Trades!V$2:V$9999)*(Trades!V$2:V$9999>0))/SUM((Trades!T$2:T$9999=Blotter!C43)*(Trades!U$2:U$9999=Blotter!B43)*(Trades!V$2:V$9999)*(Trades!V$2:V$9999>0))),SUM((Trades!T$2:T$9999=Blotter!C43)*(Trades!U$2:U$9999=Blotter!B43)*(Trades!W$2:W$9999)*(Trades!V$2:V$9999)*(Trades!V$2:V$9999>0))/SUM((Trades!T$2:T$9999=Blotter!C43)*(Trades!U$2:U$9999=Blotter!B43)*(Trades!V$2:V$9999)*(Trades!V$2:V$9999>0)),0)} -> 23.74 | Z43: =IF(C$2="Last",IF(ISNUMBER(VLOOKUP(B43,Data_IB!B:O,14,0)),VLOOKUP(B43,Data_IB!B:O,14,0),0),IF(ISNUMBER(VLOOKUP(B43,Data_IB!B:O,13,0)),VLOOKUP(B43,Data_IB!B:O,13,0),0)) -> 0
...

Sheet Cash_Mgmt
C2: COUPON | D2: ENTRY PRICE | E2: QUANTITY | F2: EXIT PRICE | G2: TOTAL | H2: RISK FREE P&L
B3: INTEREST | G3: =2060.74+768.64+6750 -> 9579.38
B4: INTEREST ACCRUALS | G4: 3376 | H4: =-G4 -> -3376
B5: T-BOND 4 CPN | H5: =(C9*E9*100) -> 0
B6: T-BOND 3 CPN | H6: =(C10*E10*100) -> 0
B7: T-BOND 2 CPN | H7: =(C11*E11*100) -> 0
B8: T-BOND CPN
B9: T-BOND 4
B10: T-BOND 3
B11: T-BOND 2
B12: T-BOND
B13: Total | G13: =SUM(G3:G12) -> 12955.38 | H13: =SUM(H3:H12) -> -3376

Sheet NAV
B2: Date | C2: ∆ Shares | D2: ∆ Capital | E2: BoP Capital $ | F2: Management Fee $ | G2: Performance Fee $ | H2: Costs $ | I2: P&L $ | J2: EoP Capital $ | K2: Shares | L2: NAV | M2: Perf. ITD | N2: Perf. MTD | O2: Volatility
B3: 45654 | J3: =L3*K3 -> 1000000 | K3: 1000 | L3: 1000 | M3: 0 | N3: 0
B4: 45685 | D4: =C4*L3 -> 0 | E4: =J3+D4 -> 1000000 | I4: -7562.17 | J4: =E4-F4-G4-H4+I4 -> 992437.83 | K4: =K3+C4 -> 1000 | L4: =J4/K4 -> 992.43783 | M4: =L4/$L$3-1 -> -0.00756217 | N4: =L4/L3-1 -> -0.00756217
B5: 45716 | D5: =C5*L4 -> 0 | E5: =J4+D5 -> 992437.83 | I5: -16180.91 | J5: =E5-F5-G5-H5+I5 -> 976256.92 | K5: =K4+C5 -> 1000 | L5: =J5/K5 -> 976.25692 | M5: =L5/$L$3-1 -> -0.02374308 | N5: =L5/L4-1 -> -0.016304205 | O5: =STDEVP(N$4:N5)*SQRT(12) -> 0.015141649
B6: 45744 | D6: =C6*L5 -> 0 | E6: =J5+D6 -> 976256.92 | I6: 46816.42 | J6: =E6-F6-G6-H6+I6 -> 1023073.3 | K6: =K5+C6 -> 1000 | L6: =J6/K6 -> 1023.0733 | M6: =L6/$L$3-1 -> 0.02307334 | N6: =L6/L5-1 -> 0.04795502 | O6: =STDEVP(N$4:N6)*SQRT(12) -> 0.098575383
