Workbook
Name DynDate: OFFSET(NAV!$B$3,0,0,COUNTA(NAV!$B:$B),1)
Name DynITD: OFFSET(NAV!$M$3,0,0,COUNTA(NAV!$M:$M)-1,1)
Name DynMTD: OFFSET(NAV!$N$3,0,0,COUNTA(NAV!$N:$N)-1,1)
Name DynNAV: OFFSET(NAV!$L$3,0,0,COUNTA(NAV!$L:$L)-1,1)

Sheet Blotter
B1: Date | C1: 46090
B2: Data | C2: Close | E2: Equity | F2: Futures
B3: AUM | C3: =OFFSET(NAV!B1,MATCH(C1,NAV!B:B,1),8) -> 999882.13 | E3: Commodities | F3: Spot
B4: P&L $ | C4: =SUM(N18:N1012) -> -117.87469 | E4: FX | F4: Call
B5: Performance ITD % | C5: =OFFSET(NAV!B1,MATCH(C1,NAV!B:B,1),11) -> -0.00011787469 | E5: Fixed income | F5: Put
B6: Performance MTD % | C6: =OFFSET(NAV!B1,MATCH(C1,NAV!B:B,1),12) -> -0.00011787469
B7: Risk-free P&L $ | C7: =Cash_Mgmt!H13 -> 0 | D7: =C7/C3 -> 0
B8: Projected P&L $ | C8: =C4+C7 -> -117.87469 | D8: =C5+D7 -> -0.00011787469
B9: Notional Futures $ | C9: {=SUM((F19:F112="Futures")*(M19:M112))} -> 96900 | D9: =C9/$C$3 -> 0.096911423
B10: Notional Call $ | C10: {=SUM((F19:F1012="Call")*(M19:M1012))} -> 0 | D10: =C10/$C$3 -> 0
B11: Notional Put $ | C11: {=SUM((F19:F212="Put")*(M19:M212))} -> 0 | D11: =C11/$C$3 -> 0
B12: Open Risk $ | C12: {=SUM((PLB!G4:G999="O")*(PLB!E4:E999))} -> 19500 | D12: =C12/$C$3 -> 0.019502299
B13: Open P&L $ | C13: {=SUM((PLB!G4:G999="O")*(PLB!D4:D999))} -> -117.87469 | D13: =C13/$C$3 -> -0.00011788859
B14: PLB Risk $ | C14: =C12+C13 -> 19382.125 | D14: =C14/$C$3 -> 0.01938441
B17: TICKER | C17: WEEK | D17: UNDERLYING | E17: ASSET CLASS | F17: INSTRUMENT | G17: MAX QUANTITY | H17: INITIAL QUANTITY | I17: QUANTITY | J17: MULTIPLIER | K17: ENTRY PRICE | L17: EXIT PRICE | M17: NOTIONAL $ | N17: P&L $ | O17: ATR | P17: INITIAL RISK | Q17: ROLL | R17: INITIAL RISK $ | S17: VOL SL | T17: VOL/EXIT-1 | U17: TECH SL | V17: TECH/EXIT -1 | X17: <0 | Y17: >0 | Z17: Market Data
B18: CASH MGMT | E18: Fixed income | N18: =Cash_Mgmt!G13 -> 0
B19: ETH.USD-PAXOS | C19: 1 | D19: ETH_PAXOS | E19: Equity | F19: Spot | G19: =VLOOKUP(D19,Multiplier!B:I,8,0) -> 63 | H19: 50 | I19: {=SUM((Trades!V$2:V$9999)*(Trades!U$2:U$9999=Blotter!B19)*(Trades!$T$2:T$9999=Blotter!C19))} -> 50 | J19: =VLOOKUP(D19,Multiplier!B:D,2,0) -> 1 | K19: =L19-N19/(H19*J19) -> 1966.6575 | L19: =IF(I19=0,IF(H19>0,X19,Y19),Z19) -> 1964.3 | M19: =I19*J19*L19 -> 98215 | N19: {=-SUM((Trades!T$2:T$9999=Blotter!C19)*(Trades!U$2:U$9999=Blotter!B19)*(Trades!V$2:V$9999)*(Trades!W$2:W$9999))*J19+SUM((Trades!T$2:T$9999=Blotter!C19)*(Trades!U$2:U$9999=Blotter!B19)*(Trades!X$2:X$9999))+(L19*I19)*J19} -> -117.87469 | O19: =VLOOKUP(D19,Multiplier!B:H,3,0) -> 140 | P19: 210 | R19: =(1-Q19)*P19*J19*H19 -> 10500 | S19: =IF(OR(F19="Futures",F19="Spot"),IF(I19=0,0,IF(I19>0,L19-O19,L19+O19)),0) -> 1824.3 | T19: =IF(S19>0,IF(ISNUMBER(S19/L19-1),S19/L19-1,0),0) -> -0.071272209 | U19: =IF(OR(F19="Futures",F19="Spot"),IF(I19=0,0,IF(I19>0,K19-P19,K19+P19)),0) -> 1756.6575 | V19: =IF(U19>0,IF(ISNUMBER(U19/L19-1),U19/L19-1,0),0) -> -0.10570814 | X19: {=IF(ISNUMBER(SUM((Trades!T$2:T$9999=Blotter!C19)*(Trades!U$2:U$9999=Blotter!B19)*(Trades!W$2:W$9999)*(Trades!V$2:V$9999)*(Trades!V$2:V$9999<0))/SUM((Trades!T$2:T$9999=Blotter!C19)*(Trades!U$2:U$9999=Blotter!B19)*(Trades!V$2:V$9999)*(Trades!V$2:V$9999<0))),SUM((Trades!T$2:T$9999=Blotter!C19)*(Trades!U$2:U$9999=Blotter!B19)*(Trades!W$2:W$9999)*(Trades!V$2:V$9999)*(Trades!V$2:V$9999<0))/SUM((Trades!T$2:T$9999=Blotter!C19)*(Trades!U$2:U$9999=Blotter!B19)*(Trades!V$2:V$9999)*(Trades!V$2:V$9999<0)),0)} -> 2000 | Y19: {=IF(ISNUMBER(SUM((Trades!T$2:T$9999=Blotter!C19)*(Trades!U$2:U$9999=Blotter!B19)*(Trades!W$2:W$9999)*(Trades!V$2:V$9999)*(Trades!V$2:V$9999>0))/SUM((Trades!T$2:T$9999=Blotter!C19)*(Trades!U$2:U$9999=Blotter!B19)*(Trades!V$2:V$9999)*(Trades!V$2:V$9999>0))),SUM((Trades!T$2:T$9999=Blotter!C19)*(Trades!U$2:U$9999=Blotter!B19)*(Trades!W$2:W$9999)*(Trades!V$2:V$9999)*(Trades!V$2:V$9999>0))/SUM((Trades!T$2:T$9999=Blotter!C19)*(Trades!U$2:U$9999=Blotter!B19)*(Trades!V$2:V$9999)*(Trades!V$2:V$9999>0)),0)} -> 1982.8 | Z19: =IF(C$2="Last",IF(ISNUMBER(VLOOKUP(B19,Prices!A:L,8,0)),VLOOKUP(B19,Prices!A:L,8,0),0),IF(ISNUMBER(VLOOKUP(B19,Prices!A:L,12,0)),VLOOKUP(B19,Prices!A:L,12,0),0)) -> 1964.3
B20: CCK6 | C20: 2 | D20: CC | E20: Equity | F20: Futures | G20: =VLOOKUP(D20,Multiplier!B:I,8,0) -> 4 | H20: 3 | I20: {=SUM((Trades!V$2:V$9999)*(Trades!U$2:U$9999=Blotter!B20)*(Trades!$T$2:T$9999=Blotter!C20))} -> 3 | J20: =VLOOKUP(D20,Multiplier!B:D,2,0) -> 10 | K20: =L20-N20/(H20*J20) -> 3230 | L20: =IF(I20=0,IF(H20>0,X20,Y20),Z20) -> 3230 | M20: =I20*J20*L20 -> 96900 | N20: {=-SUM((Trades!T$2:T$9999=Blotter!C20)*(Trades!U$2:U$9999=Blotter!B20)*(Trades!V$2:V$9999)*(Trades!W$2:W$9999))*J20+SUM((Trades!T$2:T$9999=Blotter!C20)*(Trades!U$2:U$9999=Blotter!B20)*(Trades!X$2:X$9999))+(L20*I20)*J20} -> 0 | O20: =VLOOKUP(D20,Multiplier!B:H,3,0) -> 205 | P20: 300 | R20: =(1-Q20)*P20*J20*H20 -> 9000 | S20: =IF(OR(F20="Futures",F20="Spot"),IF(I20=0,0,IF(I20>0,L20-O20,L20+O20)),0) -> 3025 | T20: =IF(S20>0,IF(ISNUMBER(S20/L20-1),S20/L20-1,0),0) -> -0.063467492 | U20: =IF(OR(F20="Futures",F20="Stocks"),IF(I20=0,0,IF(I20>0,K20-P20,K20+P20)),0) -> 2930 | V20: =IF(U20>0,IF(ISNUMBER(U20/L20-1),U20/L20-1,0),0) -> -0.092879257 | X20: {=IF(ISNUMBER(SUM((Trades!T$2:T$9999=Blotter!C20)*(Trades!U$2:U$9999=Blotter!B20)*(Trades!W$2:W$9999)*(Trades!V$2:V$9999)*(Trades!V$2:V$9999<0))/SUM((Trades!T$2:T$9999=Blotter!C20)*(Trades!U$2:U$9999=Blotter!B20)*(Trades!V$2:V$9999)*(Trades!V$2:V$9999<0))),SUM((Trades!T$2:T$9999=Blotter!C20)*(Trades!U$2:U$9999=Blotter!B20)*(Trades!W$2:W$9999)*(Trades!V$2:V$9999)*(Trades!V$2:V$9999<0))/SUM((Trades!T$2:T$9999=Blotter!C20)*(Trades!U$2:U$9999=Blotter!B20)*(Trades!V$2:V$9999)*(Trades!V$2:V$9999<0)),0)} -> 0 | Y20: {=IF(ISNUMBER(SUM((Trades!T$2:T$9999=Blotter!C20)*(Trades!U$2:U$9999=Blotter!B20)*(Trades!W$2:W$9999)*(Trades!V$2:V$9999)*(Trades!V$2:V$9999>0))/SUM((Trades!T$2:T$9999=Blotter!C20)*(Trades!U$2:U$9999=Blotter!B20)*(Trades!V$2:V$9999)*(Trades!V$2:V$9999>0))),SUM((Trades!T$2:T$9999=Blotter!C20)*(Trades!U$2:U$9999=Blotter!B20)*(Trades!W$2:W$9999)*(Trades!V$2:V$9999)*(Trades!V$2:V$9999>0))/SUM((Trades!T$2:T$9999=Blotter!C20)*(Trades!U$2:U$9999=Blotter!B20)*(Trades!V$2:V$9999)*(Trades!V$2:V$9999>0)),0)} -> 3230 | Z20: =IF(C$2="Last",IF(ISNUMBER(VLOOKUP(B20,Prices!A:L,8,0)),VLOOKUP(B20,Prices!A:L,8,0),0),IF(ISNUMBER(VLOOKUP(B20,Prices!A:L,12,0)),VLOOKUP(B20,Prices!A:L,12,0),0)) -> 3230

Sheet Cash_Mgmt
C2: COUPON | D2: ENTRY PRICE | E2: QUANTITY | F2: EXIT PRICE | G2: TOTAL | H2: RISK FREE P&L
B3: INTEREST | G3: 0
B4: INTEREST ACCRUALS | H4: =-G4 -> 0
B5: T-BOND 4 CPN | H5: =(C9*E9*100) -> 0
B6: T-BOND 3 CPN | H6: =(C10*E10*100) -> 0
B7: T-BOND 2 CPN | H7: =(C11*E11*100) -> 0
B8: T-BOND CPN
B9: T-BOND 4
B10: T-BOND 3
B11: T-BOND 2
B12: T-BOND
B13: Total | G13: =SUM(G3:G12) -> 0 | H13: =SUM(H3:H12) -> 0

Sheet NAV
B2: Date | C2: ∆ Shares | D2: ∆ Capital | E2: BoP Capital $ | F2: Management Fee $ | G2: Performance Fee $ | H2: Costs $ | I2: P&L $ | J2: EoP Capital $ | K2: Shares | L2: NAV | M2: Perf. ITD | N2: Perf. MTD | O2: Volatility
B3: 46053 | J3: =L3*K3 -> 1000000 | K3: 1000 | L3: 1000 | M3: 0 | N3: 0
B4: 46081 | D4: =C4*L3 -> 0 | E4: =J3+D4 -> 1000000 | I4: 0 | J4: =E4-F4-G4-H4+I4 -> 1000000 | K4: =K3+C4 -> 1000 | L4: =J4/K4 -> 1000 | M4: =L4/$L$3-1 -> 0 | N4: =L4/L3-1 -> 0
B5: 46112 | D5: =C5*L4 -> 0 | E5: =J4+D5 -> 1000000 | I5: =Blotter!C$4-SUM(NAV!I$4:I4) -> -117.87469 | J5: =E5-F5-G5-H5+I5 -> 999882.13 | K5: =K4+C5 -> 1000 | L5: =J5/K5 -> 999.88213 | M5: =L5/$L$3-1 -> -0.00011787469 | N5: =L5/L4-1 -> -0.00011787469 | O5: =STDEVP(N$4:N5)*SQRT(12) -> 0.00020416496

Sheet PLB
B2: DATE | C2: WEEK | D2: P&L $ | E2: RISK $ | F2: RISK-RETURN | G2: OPEN/CLOSE | H2: BoP NAV $ | I2: ∆ CAPITAL | J2: EoP NAV$ | K2: WK PERF % | L2: PERF % | M2: BoP MIN NAV $ | N2: ∆ CAPITAL | O2: EoP MIN NAV $ | P2: WK PLB % | Q2: PLB % | R2: Initial PLB % | T2: DATE | U2: WEEK | V2: INSTRUMENT | W2: THEME | X2: TECHNICAL SET-UP | Z2: INSTRUMENT | AA2: THEME | AB2: TECHNICAL SET-UP
B3: 46081 | C3: 0 | H3: 0 | I3: 1000000 | J3: =H3+I3 -> 1000000 | L3: 0 | M3: =H3 -> 0 | N3: 1000000 | O3: =M3+N3 -> 1000000 | Q3: 0 | R3: 0
B4: 46088 | C4: =C3+1 -> 1 | D4: {=SUM((Blotter!C$19:C$1013=C4)*(Blotter!N$19:N$1013)*1)} -> -117.87469 | E4: {=SUM((Blotter!B$19:C$1013=C4)*(Blotter!R$19:R$1013)*1)} -> 10500 | F4: =IF(ISNUMBER(D4/E4),D4/E4,0) -> -0.011226161 | G4: {=IF(SUM((Blotter!C$19:C$1013=PLB!C4)*(Blotter!M$19:M$1013))=0,"C","O")} -> O | H4: =J3+D4 -> 999882.13 | J4: =H4+I4 -> 999882.13 | K4: =H4/J3-1 -> -0.00011787469 | L4: =(1+K4)*(1+L3)-1 -> -0.00011787469 | M4: =O3-IF(G4="O",O3*1%,-D4) -> 990000 | N4: =I4 -> 0 | O4: =M4+N4 -> 990000 | P4: =M4/O3-1 -> -0.01 | Q4: =(1+P4)*(1+Q3)-1 -> -0.01 | R4: =(1-1%)*(1+R3)-1 -> -0.01 | T4: =B4 -> 46088 | U4: =C4 -> 1 | V4: Long ETH
B5: =B4+7 -> 46095 | C5: =C4+1 -> 2 | D5: {=SUM((Blotter!C$19:C$1013=C5)*(Blotter!N$19:N$1013)*1)} -> 0 | E5: {=SUM((Blotter!B$19:C$1013=C5)*(Blotter!R$19:R$1013)*1)} -> 9000 | F5: =IF(ISNUMBER(D5/E5),D5/E5,0) -> 0 | G5: {=IF(SUM((Blotter!C$19:C$1013=PLB!C5)*(Blotter!M$19:M$1013))=0,"C","O")} -> O | H5: =J4+D5 -> 999882.13 | J5: =H5+I5 -> 999882.13 | K5: =H5/J4-1 -> 0 | L5: =(1+K5)*(1+L4)-1 -> -0.00011787469 | M5: =O4-IF(G5="O",O4*1%,-D5) -> 980100 | N5: =I5 -> 0 | O5: =M5+N5 -> 980100 | P5: =M5/O4-1 -> -0.01 | Q5: =(1+P5)*(1+Q4)-1 -> -0.0199 | R5: =(1-1%)*(1+R4)-1 -> -0.0199 | T5: =B5 -> 46095 | U5: =C5 -> 2 | V5: Long CC

Sheet PLB_chart

Sheet Multiplier
B2: Ticker | C2: Multiplier | D2: ATR | E2: # ATR | F2: Capital $ | G2: % Risk Capital | H2: Sizing | I2: Max Sizing | J2: Price | K2: Sizing / Capital | L2: Max Sizing / Capital | N2: Capital Loc Crncy | O2: FX | P2: Capital $ | Q2: # ATR | R2: % Capital
B3: SPX | C3: 100 | D3: 42 | E3: =$Q$3 -> 1.5 | F3: =$P$3 -> 1000000 | G3: =$R$3 -> 0.01 | H3: =(F3*G3)/(C3*D3*E3) -> 1.5873016 | I3: =ROUND(H3*1.33,0) -> 2 | N3: 1000000 | O3: 1 | P3: =N3*O3 -> 1000000 | Q3: 1.5 | R3: 0.01
B4: ES | C4: 50 | D4: 50.57 | E4: =$Q$3 -> 1.5 | F4: =$P$3 -> 1000000 | G4: =$R$3 -> 0.01 | H4: =(F4*G4)/(C4*D4*E4) -> 2.6366093 | I4: =ROUND(H4*1.33,0) -> 4 | J4: 5237 | K4: =J4*H4*C4/$N$3 -> 0.69039615 | L4: =J4*I4*C4/$N$3 -> 1.0474
B5: NQ | C5: 20 | D5: 248 | E5: =$Q$3 -> 1.5 | F5: =$P$3 -> 1000000 | G5: =$R$3 -> 0.01 | H5: =(F5*G5)/(C5*D5*E5) -> 1.344086 | I5: =ROUND(H5*1.33,0) -> 2 | J5: 18320 | K5: =J5*H5*C5/$N$3 -> 0.49247312 | L5: =J5*I5*C5/$N$3 -> 0.7328
B6: RTY | C6: 50 | D6: 44.2 | E6: =$Q$3 -> 1.5 | F6: =$P$3 -> 1000000 | G6: =$R$3 -> 0.01 | H6: =(F6*G6)/(C6*D6*E6) -> 3.0165913 | I6: =ROUND(H6*1.33,0) -> 4
B7: CL | C7: 1000 | D7: 2.41 | E7: =$Q$3 -> 1.5 | F7: =$P$3 -> 1000000 | G7: =$R$3 -> 0.01 | H7: =(F7*G7)/(C7*D7*E7) -> 2.7662517 | I7: =ROUND(H7*1.33,0) -> 4 | J7: 82 | K7: =J7*H7*C7/$N$3 -> 0.22683264 | L7: =J7*I7*C7/$N$3 -> 0.328
B8: RB | C8: 42000 | D8: 0.0725 | E8: =$Q$3 -> 1.5 | F8: =$P$3 -> 1000000 | G8: =$R$3 -> 0.01 | H8: =(F8*G8)/(C8*D8*E8) -> 2.1893815 | I8: =ROUND(H8*1.33,0) -> 3
B9: NG | C9: 10000 | D9: 0.132 | E9: =$Q$3 -> 1.5 | F9: =$P$3 -> 1000000 | G9: =$R$3 -> 0.01 | H9: =(F9*G9)/(C9*D9*E9) -> 5.0505051 | I9: =ROUND(H9*1.33,0) -> 7
B10: HG | C10: 25000 | D10: 0.0708 | E10: =$Q$3 -> 1.5 | F10: =$P$3 -> 1000000 | G10: =$R$3 -> 0.01 | H10: =(F10*G10)/(C10*D10*E10) -> 3.7664783 | I10: =ROUND(H10*1.33,0) -> 5 | J10: 4.03 | K10: =J10*H10*C10/$N$3 -> 0.37947269 | L10: =J10*I10*C10/$N$3 -> 0.50375
B11: GC | C11: 100 | D11: 28.4 | E11: =$Q$3 -> 1.5 | F11: =$P$3 -> 1000000 | G11: =$R$3 -> 0.01 | H11: =(F11*G11)/(C11*D11*E11) -> 2.3474178 | I11: =ROUND(H11*1.33,0) -> 3
B12: SI | C12: 5000 | D12: 0.825 | E12: =$Q$3 -> 1.5 | F12: =$P$3 -> 1000000 | G12: =$R$3 -> 0.01 | H12: =(F12*G12)/(C12*D12*E12) -> 1.6161616 | I12: =ROUND(H12*1.33,0) -> 2 | J12: 25 | K12: =J12*H12*C12/$N$3 -> 0.2020202 | L12: =J12*I12*C12/$N$3 -> 0.25
B13: ZC | C13: 50 | D13: 8.25 | E13: =$Q$3 -> 1.5 | F13: =$P$3 -> 1000000 | G13: =$R$3 -> 0.01 | H13: =(F13*G13)/(C13*D13*E13) -> 16.161616 | I13: =ROUND(H13*1.33,0) -> 21
B14: ZW | C14: 50 | D14: 17.25 | E14: =$Q$3 -> 1.5 | F14: =$P$3 -> 1000000 | G14: =$R$3 -> 0.01 | H14: =(F14*G14)/(C14*D14*E14) -> 7.7294686 | I14: =ROUND(H14*1.33,0) -> 10 | J14: 550 | K14: =J14*H14*C14/$N$3 -> 0.21256039 | L14: =J14*I14*C14/$N$3 -> 0.275
B15: KE | C15: 50 | D15: 24.5 | E15: =$Q$3 -> 1.5 | F15: =$P$3 -> 1000000 | G15: =$R$3 -> 0.01 | H15: =(F15*G15)/(C15*D15*E15) -> 5.4421769 | I15: =ROUND(H15*1.33,0) -> 7
B16: ZS | C16: 50 | D16: 19.75 | E16: =$Q$3 -> 1.5 | F16: =$P$3 -> 1000000 | G16: =$R$3 -> 0.01 | H16: =(F16*G16)/(C16*D16*E16) -> 6.7510549 | I16: =ROUND(H16*1.33,0) -> 9 | J16: 1187 | K16: =J16*H16*C16/$N$3 -> 0.40067511 | L16: =J16*I16*C16/$N$3 -> 0.53415
B17: SB | C17: 1120 | D17: 0.89 | E17: =$Q$3 -> 1.5 | F17: =$P$3 -> 1000000 | G17: =$R$3 -> 0.01 | H17: =(F17*G17)/(C17*D17*E17) -> 6.6880685 | I17: =ROUND(H17*1.33,0) -> 9
B18: KC | C18: 375 | D18: 5.38 | E18: =$Q$3 -> 1.5 | F18: =$P$3 -> 1000000 | G18: =$R$3 -> 0.01 | H18: =(F18*G18)/(C18*D18*E18) -> 3.3044197 | I18: =ROUND(H18*1.33,0) -> 4 | J18: 184 | K18: =J18*H18*C18/$N$3 -> 0.22800496 | L18: =J18*I18*C18/$N$3 -> 0.276
B19: CC | C19: 10 | D19: 205 | E19: =$Q$3 -> 1.5 | F19: =$P$3 -> 1000000 | G19: =$R$3 -> 0.01 | H19: =(F19*G19)/(C19*D19*E19) -> 3.2520325 | I19: =ROUND(H19*1.33,0) -> 4 | J19: 3230 | K19: =J19*H19*C19/$N$3 -> 0.10504065 | L19: =J19*I19*C19/$N$3 -> 0.1292
B20: CT | C20: 500 | D20: 3.01 | E20: =$Q$3 -> 1.5 | F20: =$P$3 -> 1000000 | G20: =$R$3 -> 0.01 | H20: =(F20*G20)/(C20*D20*E20) -> 4.4296788 | I20: =ROUND(H20*1.33,0) -> 6 | J20: 94 | K20: =J20*H20*C20/$N$3 -> 0.20819491 | L20: =J20*I20*C20/$N$3 -> 0.282
B21: LE | C21: 400 | D21: 1.055 | E21: =$Q$3 -> 1.5 | F21: =$P$3 -> 1000000 | G21: =$R$3 -> 0.01 | H21: =(F21*G21)/(C21*D21*E21) -> 15.797788 | I21: =ROUND(H21*1.33,0) -> 21
B22: GF | C22: 500 | D22: 1.939 | E22: =$Q$3 -> 1.5 | F22: =$P$3 -> 1000000 | G22: =$R$3 -> 0.01 | H22: =(F22*G22)/(C22*D22*E22) -> 6.8763968 | I22: =ROUND(H22*1.33,0) -> 9
B23: HE | C23: 400 | D23: 1.579 | E23: =$Q$3 -> 1.5 | F23: =$P$3 -> 1000000 | G23: =$R$3 -> 0.01 | H23: =(F23*G23)/(C23*D23*E23) -> 10.555204 | I23: =ROUND(H23*1.33,0) -> 14
B24: DX | C24: 1000 | D24: 0.849 | E24: =$Q$3 -> 1.5 | F24: =$P$3 -> 1000000 | G24: =$R$3 -> 0.01 | H24: =(F24*G24)/(C24*D24*E24) -> 7.8523753 | I24: =ROUND(H24*1.33,0) -> 10
B25: 6A | C25: 100000 | D25: 0.00914 | E25: =$Q$3 -> 1.5 | F25: =$P$3 -> 1000000 | G25: =$R$3 -> 0.01 | H25: =(F25*G25)/(C25*D25*E25) -> 7.293946 | I25: =ROUND(H25*1.33,0) -> 10
B26: 6B | C26: 62500 | D26: 0.0124 | E26: =$Q$3 -> 1.5 | F26: =$P$3 -> 1000000 | G26: =$R$3 -> 0.01 | H26: =(F26*G26)/(C26*D26*E26) -> 8.6021505 | I26: =ROUND(H26*1.33,0) -> 11
B27: 6C | C27: 100000 | D27: 0.00559 | E27: =$Q$3 -> 1.5 | F27: =$P$3 -> 1000000 | G27: =$R$3 -> 0.01 | H27: =(F27*G27)/(C27*D27*E27) -> 11.926058 | I27: =ROUND(H27*1.33,0) -> 16
B28: 6E | C28: 125000 | D28: 0.00956 | E28: =$Q$3 -> 1.5 | F28: =$P$3 -> 1000000 | G28: =$R$3 -> 0.01 | H28: =(F28*G28)/(C28*D28*E28) -> 5.5788006 | I28: =ROUND(H28*1.33,0) -> 7
B29: 6J | C29: 12500000 | D29: 0.0001022 | E29: =$Q$3 -> 1.5 | F29: =$P$3 -> 1000000 | G29: =$R$3 -> 0.01 | H29: =(F29*G29)/(C29*D29*E29) -> 5.2185258 | I29: =ROUND(H29*1.33,0) -> 7
B30: BTC | C30: 5 | D30: 908 | E30: =$Q$3 -> 1.5 | F30: =$P$3 -> 1000000 | G30: =$R$3 -> 0.01 | H30: =(F30*G30)/(C30*D30*E30) -> 1.4684288 | I30: =ROUND(H30*1.33,0) -> 2
B31: ETH | C31: 50 | D31: 61.74 | E31: =$Q$3 -> 1.5 | F31: =$P$3 -> 1000000 | G31: =$R$3 -> 0.01 | H31: =(F31*G31)/(C31*D31*E31) -> 2.159594 | I31: =ROUND(H31*1.33,0) -> 3
B32: ZB | C32: 1000 | D32: =1+18/32 -> 1.5625 | E32: =$Q$3 -> 1.5 | F32: =$P$3 -> 1000000 | G32: =$R$3 -> 0.01 | H32: =(F32*G32)/(C32*D32*E32) -> 4.2666667 | I32: =ROUND(H32*1.33,0) -> 6
B33: BTP | C33: 1000 | D33: 1.57 | E33: =$Q$3 -> 1.5 | F33: =$P$3 -> 1000000 | G33: =$R$3 -> 0.01 | H33: =(F33*G33)/(C33*D33*E33) -> 4.2462845 | I33: =ROUND(H33*1.33,0) -> 6
B34: BABA | C34: 100 | D34: 4.15 | E34: =$Q$3 -> 1.5 | F34: =$P$3 -> 1000000 | G34: =$R$3 -> 0.01 | H34: =(F34*G34)/(C34*D34*E34) -> 16.064257 | I34: =ROUND(H34*1.33,0) -> 21
B35: NVDA | C35: 100 | D35: 9.29 | E35: =$Q$3 -> 1.5 | F35: =$P$3 -> 1000000 | G35: =$R$3 -> 0.01 | H35: =(F35*G35)/(C35*D35*E35) -> 7.1761751 | I35: =ROUND(H35*1.33,0) -> 10
B36: GOOG | C36: 100 | D36: 3.34 | E36: =$Q$3 -> 1.5 | F36: =$P$3 -> 1000000 | G36: =$R$3 -> 0.01 | H36: =(F36*G36)/(C36*D36*E36) -> 19.96008 | I36: =ROUND(H36*1.33,0) -> 27
B37: INDA | C37: 100 | D37: 0.3075 | E37: =$Q$3 -> 1.5 | F37: =$P$3 -> 1000000 | G37: =$R$3 -> 0.01 | H37: =(F37*G37)/(C37*D37*E37) -> 216.80217 | I37: =ROUND(H37*1.33,0) -> 288
B38: URA | C38: 100 | D38: 0.85 | E38: =$Q$3 -> 1.5 | F38: =$P$3 -> 1000000 | G38: =$R$3 -> 0.01 | H38: =(F38*G38)/(C38*D38*E38) -> 78.431373 | I38: =ROUND(H38*1.33,0) -> 104
B39: SAVE | C39: 100 | D39: 1.06 | E39: =$Q$3 -> 1.5 | F39: =$P$3 -> 1000000 | G39: =$R$3 -> 0.01 | H39: =(F39*G39)/(C39*D39*E39) -> 62.893082 | I39: =ROUND(H39*1.33,0) -> 84
B40: SAVE-S | C40: 1 | D40: 1.06 | E40: =$Q$3 -> 1.5 | F40: =$P$3 -> 1000000 | G40: =$R$3 -> 0.01 | H40: =(F40*G40)/(C40*D40*E40) -> 6289.3082 | I40: =ROUND(H40*1.33,0) -> 8365
B41: CYTK-S | C41: 1 | D41: 7.23 | E41: =$Q$3 -> 1.5 | F41: =$P$3 -> 1000000 | G41: =$R$3 -> 0.01 | H41: =(F41*G41)/(C41*D41*E41) -> 922.08391 | I41: =ROUND(H41*1.33,0) -> 1226 | J41: 68 | K41: =J41*H41*C41/$N$3 -> 0.062701706 | L41: =J41*I41*C41/$N$3 -> 0.083368
...

Sheet Trades
A1: ClientAccountID | B1: CurrencyPrimary | C1: AssetClass | D1: Symbol | E1: Description | F1: ListingExchange | G1: UnderlyingSymbol | H1: Multiplier | I1: Strike | J1: Expiry | K1: Put/Call | L1: TradeDate | M1: Buy/Sell | N1: Quantity | O1: Price | P1: Amount | Q1: Commission | R1: CommissionCurrency | T1: Week | U1: Ticker | V1: Quantity | W1: Price | X1: Commission | Z1: (potential conflicting VLOOKUP if same instrument traded in different weeks)
A2: DUP242961-P | B2: USD | C2: CRYPTO | D2: ETH.USD-PAXOS | E2: Ethereum cryptocurrency | H2: 1 | L2: 46084 | M2: BUY | N2: 50 | O2: 1986.6 | P2: 12116.947 | Q2: -21.810505 | R2: USD | T2: =IF(ISNUMBER(VLOOKUP(U2,Blotter!B:C,2,0)),VLOOKUP(U2,Blotter!B:C,2,0),"") -> 1 | U2: =D2 -> ETH.USD-PAXOS | V2: =N2 -> 50 | W2: =O2 -> 1986.6 | X2: =Q2 -> -21.810505 | Z2: (manually change "Week" if traded in multiple weeks)
A3: DUP242961-P | B3: USD | C3: CRYPTO | D3: ETH.USD-PAXOS | E3: Ethereum cryptocurrency | H3: 1 | L3: 46087 | M3: SELL | N3: -50 | O3: 2000 | P3: -6000 | Q3: -9.2536833 | R3: USD | T3: =IF(ISNUMBER(VLOOKUP(U3,Blotter!B:C,2,0)),VLOOKUP(U3,Blotter!B:C,2,0),"") -> 1 | U3: =D3 -> ETH.USD-PAXOS | V3: =N3 -> -50 | W3: =O3 -> 2000 | X3: =Q3 -> -9.2536833
A4: DUP242961-P | B4: USD | C4: CRYPTO | D4: ETH.USD-PAXOS | E4: Ethereum cryptocurrency | H4: 1 | L4: 46084 | M4: BUY | N4: 50 | O4: 1979 | P4: 12116.947 | Q4: -21.810505 | R4: USD | T4: =IF(ISNUMBER(VLOOKUP(U4,Blotter!B:C,2,0)),VLOOKUP(U4,Blotter!B:C,2,0),"") -> 1 | U4: =D4 -> ETH.USD-PAXOS | V4: =N4 -> 50 | W4: =O4 -> 1979 | X4: =Q4 -> -21.810505
D5: CCK6 | H5: 10 | L5: 46090 | M5: BUY | N5: 3 | O5: 3230 | T5: =IF(ISNUMBER(VLOOKUP(U5,Blotter!B:C,2,0)),VLOOKUP(U5,Blotter!B:C,2,0),"") -> 2 | U5: =D5 -> CCK6 | V5: =N5 -> 3 | W5: =O5 -> 3230 | X5: =Q5 -> 0
T6: =IF(ISNUMBER(VLOOKUP(U6,Blotter!B:C,2,0)),VLOOKUP(U6,Blotter!B:C,2,0),"") | U6: =D6 -> 0 | V6: =N6 -> 0 | W6: =O6 -> 0 | X6: =Q6 -> 0
T7: =IF(ISNUMBER(VLOOKUP(U7,Blotter!B:C,2,0)),VLOOKUP(U7,Blotter!B:C,2,0),"") | U7: =D7 -> 0 | V7: =N7 -> 0 | W7: =O7 -> 0 | X7: =Q7 -> 0
T8: =IF(ISNUMBER(VLOOKUP(U8,Blotter!B:C,2,0)),VLOOKUP(U8,Blotter!B:C,2,0),"") | U8: =D8 -> 0 | V8: =N8 -> 0 | W8: =O8 -> 0 | X8: =Q8 -> 0
T9: =IF(ISNUMBER(VLOOKUP(U9,Blotter!B:C,2,0)),VLOOKUP(U9,Blotter!B:C,2,0),"") | U9: =D9 -> 0 | V9: =N9 -> 0 | W9: =O9 -> 0 | X9: =Q9 -> 0
T10: =IF(ISNUMBER(VLOOKUP(U10,Blotter!B:C,2,0)),VLOOKUP(U10,Blotter!B:C,2,0),"") | U10: =D10 -> 0 | V10: =N10 -> 0 | W10: =O10 -> 0 | X10: =Q10 -> 0
T11: =IF(ISNUMBER(VLOOKUP(U11,Blotter!B:C,2,0)),VLOOKUP(U11,Blotter!B:C,2,0),"") | U11: =D11 -> 0 | V11: =N11 -> 0 | W11: =O11 -> 0 | X11: =Q11 -> 0
T12: =IF(ISNUMBER(VLOOKUP(U12,Blotter!B:C,2,0)),VLOOKUP(U12,Blotter!B:C,2,0),"") | U12: =D12 -> 0 | V12: =N12 -> 0 | W12: =O12 -> 0 | X12: =Q12 -> 0
T13: =IF(ISNUMBER(VLOOKUP(U13,Blotter!B:C,2,0)),VLOOKUP(U13,Blotter!B:C,2,0),"") | U13: =D13 -> 0 | V13: =N13 -> 0 | W13: =O13 -> 0 | X13: =Q13 -> 0
T14: =IF(ISNUMBER(VLOOKUP(U14,Blotter!B:C,2,0)),VLOOKUP(U14,Blotter!B:C,2,0),"") | U14: =D14 -> 0 | V14: =N14 -> 0 | W14: =O14 -> 0 | X14: =Q14 -> 0
T15: =IF(ISNUMBER(VLOOKUP(U15,Blotter!B:C,2,0)),VLOOKUP(U15,Blotter!B:C,2,0),"") | U15: =D15 -> 0 | V15: =N15 -> 0 | W15: =O15 -> 0 | X15: =Q15 -> 0
T16: =IF(ISNUMBER(VLOOKUP(U16,Blotter!B:C,2,0)),VLOOKUP(U16,Blotter!B:C,2,0),"") | U16: =D16 -> 0 | V16: =N16 -> 0 | W16: =O16 -> 0 | X16: =Q16 -> 0
T17: =IF(ISNUMBER(VLOOKUP(U17,Blotter!B:C,2,0)),VLOOKUP(U17,Blotter!B:C,2,0),"") | U17: =D17 -> 0 | V17: =N17 -> 0 | W17: =O17 -> 0 | X17: =Q17 -> 0
... T36: =IF(ISNUMBER(VLOOKUP(U36,Blotter!B:C,2,0)),VLOOKUP(U36,Blotter!B:C,2,0),"") | U36: =D36 -> 0 | V36: =N36 -> 0 | W36: =O36 -> 0 | X36: =Q36 -> 0
AB563: 25.6 | AD563: =(AB563-AA563)*V563*5000 -> 0

Sheet Config
A1: IB / Excel Live Feed (Replacement for HoadleyNet RTD)
A3: Host | B3: 127.0.0.1
A4: Port | B4: 7497
A5: ClientId | B5: 11
A6: UpdateIntervalSec | B6: 0.25
A7: Mode | B7: STREAM
A8: MarketDataType | B8: 3
A10: Notes
A11: 1) Enable API in TWS: Configure > API > Settings: 'Enable ActiveX and Socket Clients' + port 7497.
A12: 2) Run: python ib_excel_feed.py --file IB_Excel_Feed.xlsx
A13: 3) Your model references Prices sheet cells.

Sheet Symbols
A1: enabled | B1: name | C1: secType | D1: symbol | E1: exchange | F1: currency | G1: lastTradeDateOrContractMonth | H1: strike | I1: right | J1: multiplier | K1: tradingClass | L1: localSymbol | M1: primaryExchange
A2: 1 | B2: ESH6 | C2: FUT | D2: ES | E2: CME | F2: USD | G2: 202606
A3: 1 | B3: NQH6 | C3: FUT | D3: NQ | E3: CME | F3: USD | G3: 202606
A4: 1 | B4: RTYH6 | C4: FUT | D4: RTY | E4: CME | F4: USD | G4: 202606
A5: 1 | B5: FESXH6 | C5: FUT | D5: FESX | E5: EUREX | F5: EUR | G5: 202606 | K5: FESX
A6: 1 | B6: DAXH6 | C6: FUT | D6: DAX | E6: EUREX | F6: EUR | G6: 202606 | K6: FDXM
A7: 1 | B7: NIYH6 | C7: FUT | D7: NIY | E7: CME | F7: JPY | G7: 202606 | J7: 500 | K7: NIY
A8: 1 | B8: CLJ4 | C8: FUT | D8: CL | E8: NYMEX | F8: USD | G8: 202604 | K8: CL
A9: 1 | B9: NGH6 | C9: FUT | D9: NG | E9: NYMEX | F9: USD | G9: 202606 | K9: NG
A10: 1 | B10: RBH6 | C10: FUT | D10: RB | E10: NYMEX | F10: USD | G10: 202606 | K10: RB
A11: 1 | B11: GCH6 | C11: FUT | D11: GC | E11: COMEX | F11: USD | G11: 202606 | K11: GC
A12: 1 | B12: SIH6 | C12: FUT | D12: SI | E12: COMEX | F12: USD | G12: 202606 | K12: SI
A13: 1 | B13: HGH6 | C13: FUT | D13: HG | E13: COMEX | F13: USD | G13: 202606 | K13: HG
A14: 1 | B14: ZCZ3 | C14: FUT | D14: ZC | E14: CBOT | F14: USD | G14: 202605 | K14: ZC
A15: 1 | B15: ZWK4 | C15: FUT | D15: ZW | E15: CBOT | F15: USD | G15: 202605 | K15: ZW
A16: 1 | B16: ZSK4 | C16: FUT | D16: ZS | E16: CBOT | F16: USD | G16: 202605 | K16: ZS
A17: 1 | B17: SBV3 | C17: FUT | D17: SB | E17: NYBOT | F17: USD | G17: 202605 | K17: SB
A18: 1 | B18: KCK4 | C18: FUT | D18: KC | E18: NYBOT | F18: USD | G18: 202605 | K18: KC
A19: 1 | B19: CCK6 | C19: FUT | D19: CC | E19: NYBOT | F19: USD | G19: 202605 | K19: CC
A20: 1 | B20: CTN4 | C20: FUT | D20: CT | E20: NYBOT | F20: USD | G20: 202605 | K20: CT
A21: 1 | B21: LE | C21: FUT | D21: LE | E21: CME | F21: USD | G21: 202604 | K21: LE
A22: 1 | B22: GF | C22: FUT | D22: GF | E22: CME | F22: USD | G22: 202605 | K22: GF
A23: 1 | B23: HEG3 | C23: FUT | D23: HE | E23: CME | F23: USD | G23: 202604 | K23: HE
A24: 1 | B24: DXYH6 | C24: FUT | D24: DX | E24: NYBOT | F24: USD | G24: 202606 | K24: DX
A25: 1 | B25: 6EH6 | C25: FUT | D25: 6E | E25: CME | F25: USD | G25: 202606 | K25: 6E
A26: 1 | B26: 6BH6 | C26: FUT | D26: 6B | E26: CME | F26: USD | G26: 202606 | K26: 6B
A27: 1 | B27: 6JH6 | C27: FUT | D27: 6J | E27: CME | F27: USD | G27: 202606 | K27: 6J
A28: 1 | B28: 6CH6 | C28: FUT | D28: 6C | E28: CME | F28: USD | G28: 202606 | K28: 6C
A29: 1 | B29: 6AH6 | C29: FUT | D29: 6A | E29: CME | F29: USD | G29: 202606 | K29: 6A
A30: 1 | B30: ZBH6 | C30: FUT | D30: ZB | E30: CBOT | F30: USD | G30: 202606 | K30: ZB
A31: 1 | B31: ZNH6 | C31: FUT | D31: ZN | E31: CBOT | F31: USD | G31: 202606 | K31: ZN
A32: 1 | B32: GBLH6 | C32: FUT | D32: FGBL | E32: EUREX | F32: EUR | G32: 202606 | K32: FGBL
A33: 1 | B33: BUXLH6 | C33: FUT | D33: FGBX | E33: EUREX | F33: EUR | G33: 202606 | K33: FGBX
A34: 1 | B34: BTPH6 | C34: FUT | D34: FBTP | E34: EUREX | F34: EUR | G34: 202606 | K34: FBTP
A35: 1 | B35: BTC.USD-PAXOS | C35: CRYPTO | D35: BTC | E35: PAXOS | F35: USD
A36: 1 | B36: ETH.USD-PAXOS | C36: CRYPTO | D36: ETH | E36: PAXOS | F36: USD
C55: SIZ3 | D55: SI | E55: FUT | F55: COMEX | G55: USD
C56: PA | D56: PA | E56: FUT | F56: NYMEX | G56: USD
C57: ZCZ3 | D57: ZC | E57: FUT | F57: CBOT | G57: USD
C58: ZWK4 | D58: ZW | E58: FUT | F58: CBOT | G58: USD
...

Sheet Prices
A1: name | B1: conId | C1: secType | D1: symbol | E1: localSymbol | F1: exchange | G1: currency | H1: last | I1: bid | J1: ask | K1: mid | L1: close | M1: open | N1: high | O1: low | P1: volume | Q1: impliedVol | R1: delta | S1: gamma | T1: vega | U1: theta | V1: timestamp | W1: status
A2: ESH6 | B2: 649180678 | C2: FUT | D2: ES | E2: ESM6 | F2: CME | G2: USD | H2: 6694.5 | I2: 6693.5 | J2: 6694.5 | K2: 6694 | L2: 6794 | M2: 6742.5 | N2: 6742.5 | O2: 6631.5 | P2: 10075 | V2: 46090.385 | W2: OK
A3: NQH6 | B3: 750150196 | C3: FUT | D3: NQ | E3: NQM6 | F3: CME | G3: USD | H3: 24491.25 | I3: 24478.25 | J3: 24484.25 | K3: 24481.25 | L3: 24883.25 | M3: 24764.75 | N3: 24764.75 | O3: 24212.25 | P3: 2804 | V3: 46090.385 | W3: OK
A4: RTYH6 | B4: 770561234 | C4: FUT | D4: RTY | E4: RTYM6 | F4: CME | G4: USD | H4: 2476.9 | I4: 2474.7 | J4: 2476 | K4: 2475.35 | L4: 2543.4 | M4: 2524.9 | N4: 2524.9 | O4: 2434 | P4: 1238 | V4: 46090.385 | W4: OK
A5: FESXH6 | B5: 638120304 | C5: FUT | D5: ESTX50 | E5: FESX 20260619 M | F5: EUREX | G5: EUR | H5: 5495 | I5: 5501 | J5: 5504 | K5: 5502.5 | L5: 5645 | M5: 5545 | N5: 5545 | O5: 5463 | P5: 1994 | V5: 46090.385 | W5: OK
A6: DAXH6 | B6: 638120262 | C6: FUT | D6: DAX | E6: FDXM 20260619 M | F6: EUREX | G6: EUR | H6: 23227 | I6: 23184 | J6: 23242 | K6: 23213 | L6: 23768 | M6: 23369 | N6: 23369 | O6: 22955 | P6: 58 | V6: 46090.385 | W6: OK
A7: NIYH6 | B7: 635680486 | C7: FUT | D7: NIY | E7: NIYM6 | F7: CME | G7: JPY | H7: 52490 | I7: 52135 | J7: 52185 | K7: 52160 | L7: 53800 | M7: 53130 | N7: 53130 | O7: 51025 | P7: 4322 | V7: 46090.385 | W7: OK
A8: CLJ4 | B8: 304037436 | C8: FUT | D8: CL | E8: CLJ6 | F8: NYMEX | G8: USD | H8: 102.13 | I8: 102.11 | J8: 102.16 | K8: 102.135 | L8: 90.9 | M8: 98 | N8: 119.48 | O8: 98 | P8: 429857 | V8: 46090.385 | W8: OK
A9: NGH6 | B9: 269460069 | C9: FUT | D9: NG | E9: NGM26 | F9: NYMEX | G9: USD | H9: 3.498 | I9: 3.495 | J9: 3.499 | K9: 3.497 | L9: 3.351 | M9: 3.429 | N9: 3.622 | O9: 3.429 | P9: 12611 | V9: 46090.385 | W9: OK
A10: RBH6 | B10: 600696533 | C10: FUT | D10: RB | E10: RBM6 | F10: NYMEX | G10: USD | H10: 2.8633 | I10: 2.8628 | J10: 2.8646 | K10: 2.8637 | L10: 2.6304 | M10: 2.7 | N10: 3.0407 | O10: 2.6825 | P10: 43129 | V10: 46090.385 | W10: OK
A11: GCH6 | B11: 430360630 | C11: FUT | D11: GC | E11: GCM6 | F11: COMEX | G11: USD | H11: 5152.7 | I11: 5155 | J11: 5155.7 | K11: 5155.35 | L11: 5197.9 | M11: 5236 | N11: 5244.3 | O11: 5060 | P11: 5510 | V11: 46090.385 | W11: OK
A12: SIH6 | B12: 760200596 | C12: FUT | D12: SI | E12: SIM6 | F12: COMEX | G12: USD | H12: 84.045 | I12: 84.14 | J12: 84.205 | K12: 84.1725 | L12: 84.62 | M12: 84.805 | N12: 85.155 | O12: 80 | P12: 268 | V12: 46090.385 | W12: OK
A13: HGH6 | B13: 712565973 | C13: FUT | D13: HG | E13: HGM6 | F13: COMEX | G13: USD | H13: 5.781 | I13: 5.7765 | J13: 5.7785 | K13: 5.7775 | L13: 5.835 | M13: 5.8 | N13: 5.8 | O13: 5.6785 | P13: 111 | V13: 46090.385 | W13: OK
... A16: ZSK4 | B16: 665643569 | C16: FUT | D16: ZS | E16: ZSK6 | F16: CBOT | G16: USD | H16: 1216.5 | I16: 1216.5 | J16: 1216.75 | K16: 1216.625 | L16: 1200.75 | M16: 1219.5 | N16: 1233.75 | O16: 1210.5 | P16: 62655 | V16: 46090.385 | W16: OK
A17: SBV3 | B17: 634760175 | C17: FUT | D17: SB | E17: SBK6 | F17: NYBOT | G17: USD | H17: 0 | I17: -100 | J17: -100 | K17: -100 | L17: 14.1 | M17: 0 | P17: 0 | V17: 46090.385 | W17: OK
A18: KCK4 | B18: 634760204 | C18: FUT | D18: KC | E18: KCK6 | F18: NYBOT | G18: USD | H18: 0 | I18: -100 | J18: -100 | K18: -100 | L18: 293.3 | M18: 0 | P18: 0 | V18: 46090.385 | W18: OK
A19: CCK6 | B19: 707621000 | C19: FUT | D19: CC | E19: CCK6 | F19: NYBOT | G19: USD | H19: 0 | I19: -1 | J19: -1 | K19: -1 | L19: 3230 | M19: 0 | P19: 0 | V19: 46090.385 | W19: OK
A20: CTN4 | B20: 634760245 | C20: FUT | D20: CT | E20: CTK6 | F20: NYBOT | G20: USD | H20: 64.63 | I20: 64.62 | J20: 64.64 | K20: 64.63 | L20: 64.2 | M20: 64.2 | N20: 65.02 | O20: 64.08 | P20: 9893 | V20: 46090.385 | W20: OK
A21: LE | B21: 738739101 | C21: FUT | D21: LE | E21: LEJ6 | F21: CME | G21: USD | H21: 0 | I21: -100 | J21: -100 | K21: -100 | L21: 234.575 | M21: 0 | P21: 0 | V21: 46090.385 | W21: OK
A22: GF | B22: 786686904 | C22: FUT | D22: GF | E22: GFK6 | F22: CME | G22: USD | H22: 0 | I22: -100 | J22: -100 | K22: -100 | L22: 348.075 | M22: 0 | P22: 0 | V22: 46090.385 | W22: OK
A23: HEG3 | B23: 735014937 | C23: FUT | D23: HE | E23: HEJ6 | F23: CME | G23: USD | H23: 0 | I23: -100 | J23: -100 | K23: -100 | L23: 95.625 | M23: 0 | P23: 0 | V23: 46090.385 | W23: OK
A24: DXYH6 | B24: 792232100 | C24: FUT | D24: DX | E24: DXM6 | F24: NYBOT | G24: USD | H24: 99.02 | I24: 99.02 | J24: 99.03 | K24: 99.025 | L24: 98.71 | M24: 99.04 | N24: 99.435 | O24: 98.965 | P24: 3043 | V24: 46090.385 | W24: OK
A25: 6EH6 | B25: 496647057 | C25: FUT | D25: EUR | E25: 6EM6 | F25: CME | G25: USD | H25: 1.16165 | I25: 1.16145 | J25: 1.16155 | K25: 1.1615 | L25: 1.16555 | M25: 1.1604 | N25: 1.16245 | O25: 1.1561 | P25: 14661 | V25: 46090.385 | W25: OK
A26: 6BH6 | B26: 496647091 | C26: FUT | D26: GBP | E26: 6BM6 | F26: CME | G26: USD | H26: 1.3347 | I26: 1.3344 | J26: 1.3346 | K26: 1.3345 | L26: 1.3387 | M26: 1.3351 | N26: 1.3351 | O26: 1.3283 | P26: 10401 | V26: 46090.385 | W26: OK
A27: 6JH6 | B27: 496647108 | C27: FUT | D27: JPY | E27: 6JM6 | F27: CME | G27: USD | H27: 0.006367 | I27: 0.006366 | J27: 0.006367 | K27: 0.0063665 | L27: 0.006388 | M27: 0.00638 | N27: 0.00638 | O27: 0.0063465 | P27: 30276 | V27: 46090.385 | W27: OK
A28: 6CH6 | B28: 496879111 | C28: FUT | D28: CAD | E28: 6CM6 | F28: CME | G28: USD | H28: 0.7408 | I28: 0.7407 | J28: 0.7408 | K28: 0.74075 | L28: 0.7392 | M28: 0.73875 | N28: 0.7414 | O28: 0.738 | P28: 3189 | V28: 46090.385 | W28: OK
A29: 6AH6 | B29: 496647009 | C29: FUT | D29: AUD | E29: 6AM6 | F29: CME | G29: USD | H29: 0.7 | I29: 0.6999 | J29: 0.7 | K29: 0.69995 | L29: 0.7019 | M29: 0.69835 | N29: 0.70155 | O29: 0.6949 | P29: 11221 | V29: 46090.385 | W29: OK
A30: ZBH6 | B30: 815824224 | C30: FUT | D30: ZB | E30: ZBM6 | F30: CBOT | G30: USD | H30: 115.40625 | I30: 115.375 | J30: 115.40625 | K30: 115.39062 | L30: 116.1875 | M30: 115.8125 | N30: 115.84375 | O30: 115.0625 | P30: 116350 | V30: 46090.385 | W30: OK
A31: ZNH6 | B31: 815824229 | C31: FUT | D31: ZN | E31: ZNM6 | F31: CBOT | G31: USD | H31: 111.98438 | I31: 111.98438 | J31: 112 | K31: 111.99219 | L31: 112.4375 | M31: 112.1875 | N31: 112.20312 | O31: 111.82812 | P31: 637038 | V31: 46090.385 | W31: OK
A32: GBLH6 | B32: 813041669 | C32: FUT | D32: GBL | E32: FGBL 20260608 M | F32: EUREX | G32: EUR | H32: 126.5 | I32: 126.49 | J32: 126.5 | K32: 126.495 | L32: 126.93 | M32: 126.7 | N32: 126.7 | O32: 125.94 | P32: 353033 | V32: 46090.385 | W32: OK
A33: BUXLH6 | B33: 813041681 | C33: FUT | D33: GBX | E33: FGBX 20260608 M | F33: EUREX | G33: EUR | H33: 111.38 | I33: 111.36 | J33: 111.38 | K33: 111.37 | L33: 110.88 | M33: 111 | N33: 111.64 | O33: 110.14 | P33: 49976 | V33: 46090.385 | W33: OK
A34: BTPH6 | B34: 813041663 | C34: FUT | D34: BTP | E34: FBTP 20260608 M | F34: EUREX | G34: EUR | H34: 117.61 | I34: 117.61 | J34: 117.62 | K34: 117.615 | L34: 118.6 | M34: 117.62 | N34: 117.84 | O34: 117.42 | P34: 81733 | V34: 46090.385 | W34: OK
A35: BTC.USD-PAXOS | B35: 479624278 | C35: CRYPTO | D35: BTC | E35: BTC.USD | F35: PAXOS | G35: USD | H35: 67524.5 | I35: 67524.5 | J35: 67524.75 | K35: 67524.625 | L35: 67317.25 | N35: 68748 | O35: 65471 | P35: 148.76281 | V35: 46090.385 | W35: OK
A36: ETH.USD-PAXOS | B36: 495759171 | C36: CRYPTO | D36: ETH | E36: ETH.USD | F36: PAXOS | G36: USD | H36: 1985.5 | I36: 1985.45 | J36: 1985.5 | K36: 1985.475 | L36: 1964.3 | N36: 2013.05 | O36: 1914.8 | P36: 1704.4242 | V36: 46090.385 | W36: OK

Sheet Log
A1: timestamp | B1: level | C1: message
A2: 46086.543 | B2: INFO | C2: Starting. host=127.0.0.1 port=7497 clientId=11 mktDataType=3 interval=0.25s
A3: 46086.543 | B3: INFO | C3: Connected to TWS.
A4: 46086.543 | B4: INFO | C4: Loaded 35 contracts from Symbols sheet.
A5: 46090.384 | B5: INFO | C5: Starting. host=127.0.0.1 port=7497 clientId=11 mktDataType=3 interval=0.25s
A6: 46090.384 | B6: INFO | C6: Connected to TWS.
A7: 46090.384 | B7: INFO | C7: Loaded 35 contracts from Symbols sheet.
